Workbook
Name AllUnits: LISTS!#REF!
Name FunderList: OFFSET(LISTS!$W$2,0,0,COUNTA(LISTS!$W$2:$W$255),1)
Name LookupDeptByUnit: LISTS!#REF!
Name ResponsibleList: OFFSET(LISTS!$T$2,0,0,COUNTA(LISTS!$T$2:$T$255),1)
Name rng_Alert: DATA!$AJ$2:$AJ$476
Name rng_Dept: DATA!$I$2:$I$476
Name rng_KPI: DATA!$AG$2:$AG$476
Name rng_Monitor: DATA!$AI$2:$AI$476

Sheet LISTS
A1: المركز الرئيسي | B1: الدائرة | C1: الجهة | Q1: نوع النشاط | S1: المراقب | T1: المسؤول عن النشاط | U1: اسم المشروع | V1: رقم المشروع | W1: * الممول | Y1: الجمعية | Z1: المراكز الصحية | AB1: سكرتاريا | AC1: دائرة الشؤون الإدارية | AD1: دائرة التنمية الاجتماعية | AE1: دائرة المشاريع والتسويق والإعلام | AF1: دائرة الشؤون المالية | AG1: دائرة الاستثمار الخيري | AH1: يافا | AI1: الكويتي | AJ1: الوسطى | AL1: تسمية التنفيذ | AM1: قيمة التنفيذ | AO1: تسمية الجودة | AP1: قيمة الجودة | AR1: تسمية الإغلاق | AS1: قيمة الإغلاق | AU1: تسمية الخصم | AV1: قيمة الخصم
A2: {=_xlfn.LET( _xlpm.hdr, AB1:AJ1, _xlpm.body, AB2:AJ30, _xlpm.res, _xlfn.DROP(_xlfn.REDUCE("",_xlfn.SEQUENCE(COLUMNS(_xlpm.hdr)), _xlfn.LAMBDA(_xlpm.acc,_xlpm.i, _xlfn.LET( _xlpm.d, INDEX(_xlpm.hdr,1,_xlpm.i), _xlpm.units, _xlfn._xlws.FILTER(INDEX(_xlpm.body,0,_xlpm.i), INDEX(_xlpm.body,0,_xlpm.i)<>""," "), _xlpm.ctr, IF(ISNUMBER(MATCH(_xlpm.d,$Y$2:$Y$8,0)), $Y$1, $Z$1), IF(_xlpm.d="", _xlpm.acc, _xlfn.VSTACK(_xlpm.acc, _xlfn.HSTACK(IF(_xlpm.units="",_xlpm.ctr,_xlpm.ctr), IF(_xlpm.units="",_xlpm.d,_xlpm.d), _xlpm.units))) ) )),1), _xlpm.res )} -> الجمعية | B2: سكرتاريا | C2: سكرتير المجلس | Q2: تفتيش ميداني | S2: سمير نصار | T2: جهاد محمد محروس ابو الريش | U2: الرغيف الخيري | V2: سكودا فابيا | W2: مؤسسة المناصرة الأردنية | Y2: سكرتاريا | Z2: يافا | AB2: سكرتير المجلس | AC2: قسم شؤون الموظفين | AD2: قسم الأيتام والأسر | AE2: مكتب خانيونس | AF2: قسم الحسابات | AG2: قسم التعليم | AH2: عيادة مسالك بولية | AI2: قسم البانوراما | AJ2: عيادة الاسنان- رجال | AL2: ممتاز 100% | AM2: 100 | AO2: ممتاز 100% | AP2: 100 | AR2: مكتمل 100% | AS2: 100 | AU2: لا خصم 0 | AV2: 0
A3: الجمعية | B3: سكرتاريا | C3: سكرتير | Q3: جودة خدمة | S3: اياد أبو عبدو | T3: محمود سالم هزاع القريناوي | U3: متابعة السيارات | V3: باص تيوتا | W3: مؤسسة أحباء غزة ماليزيا | Y3: دائرة الشؤون الإدارية | Z3: الكويتي | AB3: سكرتير | AC3: قسم تنمية الموارد البشرية | AD3: المدارس | AE3: مكتب رفح | AF3: قسم المشتريات | AG3: قسم الزراعة | AH3: عيادة فحص السمع | AI3: قسم الايكو اطفال | AJ3: عيادة عظام | AL3: مقبول 60% | AM3: 60 | AO3: جيد 85% | AP3: 85 | AR3: معلق 30% | AS3: 30 | AU3: مخالفة −25 | AV3: 25
A4: الجمعية | B4: دائرة الشؤون الإدارية | C4: قسم شؤون الموظفين | Q4: فحص سلامة | S4: محمد حسن | T4: بسام محمد حميدان الخطيب | U4: كسوة صيفية | V4: كرافتر 1 | W4: أوردا H.H | Y4: دائرة التنمية الاجتماعية | Z4: الوسطى | AC4: قسم الحاسوب والشبكات | AE4: مكتب دير البلح | AF4: قسم المخازن | AG4: قسم المشاريع التنموية | AH4: عيادة النطق | AI4: قسم الايكو Echo | AJ4: عيادة طب العيون | AL4: جيد 80% | AM4: 80 | AO4: مقبول 70% | AP4: 70 | AR4: جزئي 60% | AS4: 60 | AU4: امتثال −20 | AV4: 20
A5: الجمعية | B5: دائرة الشؤون الإدارية | C5: قسم تنمية الموارد البشرية | Q5: فحص مخزون | T5: طارق حسن ع.القادر قنديل | U5: توزيع أدوات منزلية | V5: سكودا اسود | W5: Cousins/London | Y5: دائرة المشاريع والتسويق والإعلام | AC5: قسم الصيانة العامة | AE5: مكتب المغازي | AF5: قسم الموازنة والتدقيق | AG5: مطبخ البركة | AH5: عيادة النساء | AI5: قسم الألتراساوند US | AJ5: عيادة طب اسرة | AL5: خطر 40% | AM5: 40 | AO5: ضعيف 50% | AP5: 50 | AR5: مفتوح 0% | AS5: 0 | AU5: عجز −10 | AV5: 10
A6: الجمعية | B6: دائرة الشؤون الإدارية | C6: قسم الحاسوب والشبكات | Q6: متابعة شكاوى | T6: جيهان سليمان ابراهيم برهوم | U6: حفر بئر مياه | V6: باص كرافتر 2 | W6: G2G | Y6: دائرة الشؤون المالية | AC6: قسم الخدمات | AE6: مكتب الزوايدة | AG6: مطبخ الزيناتي / خارجي | AH6: عيادة الاوعية الدموية | AI6: قسم الأشعة المقطعية CT | AJ6: عيادة جلدية | AU6: تأخير −5 | AV6: 5
A7: الجمعية | B7: دائرة الشؤون الإدارية | C7: قسم الصيانة العامة | Q7: مراجعة إجراءات | T7: سمية عطا خليل أبو معروف | U7: مشروع صحي | V7: شحن مرسيدس 418 | W7: HANA IMAN | Y7: دائرة الاستثمار الخيري | AE7: مكتب البريج | AG7: عمارة سعد | AH7: عيادة الاسنان- رجال | AI7: قسم اشعة | AJ7: عيادة جراحة واعصاب | AU7: جودة −15 | AV7: 15
A8: الجمعية | B8: دائرة الشؤون الإدارية | C8: قسم الخدمات | Q8: جرد مفاجئ | T8: عماد عبد المنعم خليل نطط | U8: احذية أطفال | V8: عمارة سعد | W8: SOUTHHALL FAMILY | AE8: مكتب غزة | AG8: عمارة المدينة | AH8: عيادة اسنان -نساء | AJ8: بانوراما اشعة
A9: الجمعية | B9: دائرة التنمية الاجتماعية | C9: قسم الأيتام والأسر | Q9: مراجعة عقود | T9: هديل سعيد احمد نصار | U9: ادوية طبية | V9: نشاط مكتب | W9: VIP | AE9: مكتب جباليا | AH9: عيادة عظام | AJ9: عيادة باطنة
A10: الجمعية | B10: دائرة التنمية الاجتماعية | C10: المدارس | Q10: تدقيق مالي | T10: باسم ديب عبد الله المبحوح | U10: اغاثة أسرة | V10: شكوى | W10: الاقصى اليمن | AE10: قسم المشاريع | AH10: عيادة طب العيون | AJ10: المختبر
A11: الجمعية | B11: دائرة المشاريع والتسويق والإعلام | C11: مكتب خانيونس | Q11: متابعة حضور | T11: سالم احمد حسين البحيصي | U11: افطار صائم | W11: الإنتربال | AE11: قسم التسويق | AH11: عيادة جلدية | AJ11: عيادة العلاج الطبيعي
A12: الجمعية | B12: دائرة المشاريع والتسويق والإعلام | C12: مكتب رفح | T12: مؤمنة نعيم علي الطويل | U12: امانات | W12: الإنتربال | AE12: قسم الإعلام | AH12: عيادة جراحة واعصاب | AJ12: الصيدلية
A13: الجمعية | B13: دائرة المشاريع والتسويق والإعلام | C13: مكتب دير البلح | T13: خلود تيسير محمود الجوراني | U13: إنشاء مصلى | W13: الإيسيكو | AE13: متابعة السيارات | AH13: عيادة جراحة عامة | AJ13: عيادة اذن وانف حنجرة
A14: الجمعية | B14: دائرة المشاريع والتسويق والإعلام | C14: مكتب المغازي | T14: سعيد فرج محمد أبو جزر | U14: بسطة سكاكر وحلوى | W14: الدولي | AH14: عيادة بصريات
A15: الجمعية | B15: دائرة المشاريع والتسويق والإعلام | C15: مكتب الزوايدة | T15: سمير نصار | U15: بسكويت | W15: السيدة / Farida Umar
A16: الجمعية | B16: دائرة المشاريع والتسويق والإعلام | C16: مكتب البريج | T16: عبد القادر صلاح الدين علي ابو جلهوم | U16: بكج هدايا | W16: المناصرة - اسبانيا | AH16: المختبر
A17: الجمعية | B17: دائرة المشاريع والتسويق والإعلام | C17: مكتب غزة | T17: محمد إبراهيم عودة بدوان | U17: ترميم منزل | W17: المناصرة الأردنية | AH17: عيادة العمليات
A18: الجمعية | B18: دائرة المشاريع والتسويق والإعلام | C18: مكتب جباليا | T18: ميسرة سالم عبد القادر موسى | U18: تشغيل خريجين | W18: المناصرة الأردينة | AH18: عيادة العلاج الطبيعي
A19: الجمعية | B19: دائرة المشاريع والتسويق والإعلام | C19: قسم المشاريع | T19: ابراهيم اسماعيل ابراهيم حرب | U19: تكية | W19: المؤسسة التركية | AH19: الصيدلية
A20: الجمعية | B20: دائرة المشاريع والتسويق والإعلام | C20: قسم التسويق | T20: ابراهيم عطا ابراهيم سلمان | U20: جلباب بناتي | W20: الوافاء- صندوق الخير | AH20: عيادة اذن وانف حنجرة
A21: الجمعية | B21: دائرة المشاريع والتسويق والإعلام | C21: قسم الإعلام | T21: احمد إسماعيل إبراهيم حرب | U21: جهاز حاسوب | W21: الوافاء - جمعية كاف
A22: الجمعية | B22: دائرة المشاريع والتسويق والإعلام | C22: متابعة السيارات | T22: احمد إسماعيل ماضي أبو ماضي | U22: حطب للطهي | W22: الوفاء - saf
A23: الجمعية | B23: دائرة الشؤون المالية | C23: قسم الحسابات | T23: احمد سعيد احمد نصار | U23: حفل | W23: الوفاء - اخوات الفينو الرحيق المختوم
A24: الجمعية | B24: دائرة الشؤون المالية | C24: قسم المشتريات | T24: احمد صالح سليمان أبو عرمانة | U24: حليب أطفال | W24: الوفاء - الامل العالمية أحمد التلة
A25: الجمعية | B25: دائرة الشؤون المالية | C25: قسم المخازن | T25: احمد وائل احمد بركة | U25: خزعات المركز الكويتي | W25: الوفاء - الانوار
A26: الجمعية | B26: دائرة الشؤون المالية | C26: قسم الموازنة والتدقيق | T26: اسراء خميس خليل أبو كريم | U26: خيام | W26: الوفاء - الأخت نادية من الكويت
A27: الجمعية | B27: دائرة الاستثمار الخيري | C27: قسم التعليم | T27: اسماء كمال حمودة زمزم - "دلو" | U27: خيام + شادر | W27: الوفاء - التاجر التركي
A28: الجمعية | B28: دائرة الاستثمار الخيري | C28: قسم الزراعة | T28: اعتماد احمد محمد تمراز | U28: زكاة مال | W28: الوفاء - الحاج محمد الخالدي
A29: الجمعية | B29: دائرة الاستثمار الخيري | C29: قسم المشاريع التنموية | T29: المعتصم بالله محمد روحي يوسف الحداد | U29: سقيا ماء | W29: الوفاء - المصطفى
A30: الجمعية | B30: دائرة الاستثمار الخيري | C30: مطبخ البركة | T30: اميرة محمد محمد مدوخ | U30: سلال خضار | W30: الوفاء - الهلال الدنماركي
A31: الجمعية | B31: دائرة الاستثمار الخيري | C31: مطبخ الزيناتي / خارجي | T31: انس بشير عبد المجيد قفة | U31: شراء دابة | W31: الوفاء - ايسر 1
A32: الجمعية | B32: دائرة الاستثمار الخيري | C32: عمارة سعد | T32: انعام فضل صابر أبو عيسى | U32: شراء لحوم | W32: الوفاء - أبو عبد الرحمن
... A59: المراكز الصحية | B59: الوسطى | C59: عيادة عظام | T59: سعيد عواد مسلم ابو شحادة | U59: كفالات | W59: ألدو رادو - أبو محمد غريب
A60: المراكز الصحية | B60: الوسطى | C60: عيادة طب العيون | T60: سلامة يوسف سلامة ابو خطاب | W60: ألدو رادو - أبو محمد غريب
A61: المراكز الصحية | B61: الوسطى | C61: عيادة طب اسرة | T61: سماح محمد احمد اسليم(الحبشي) | W61: أمل الأمة
A62: المراكز الصحية | B62: الوسطى | C62: عيادة جلدية | T62: سناء حمد اسليم ابو عمرة | W62: أمين اسليم
A63: المراكز الصحية | B63: الوسطى | C63: عيادة جراحة واعصاب | T63: سهاري سمير خليل درويش | W63: أمين أند فاميلي
A64: المراكز الصحية | B64: الوسطى | C64: بانوراما اشعة | T64: سهيل جميل عبد الفتاح ابو العطا | W64: أوردا
A65: المراكز الصحية | B65: الوسطى | C65: عيادة باطنة | T65: شادي احمد علي الحاج علي | W65: أوردا- اليوم الأول
A66: المراكز الصحية | B66: الوسطى | C66: المختبر | T66: صابر صالح عطا الله والي | W66: أوردا- اليوم الثالث
...

Sheet DATA
A1: التسلسل | B1: اليوم | C1: مرجع النشاط | D1: ✓ تحقق | E1: التاريخ | F1: الوقت | G1: المركز الرئيسي | H1: الدائرة | I1: القسم / الإدارة | J1: المسؤول عن النشاط | K1: نوع النشاط | L1: اسم المشروع | M1: رقم/ المشروع | N1: الممول | O1: مدير المشروع | P1: عدد المستفيدين | Q1: عدد مناطق التنفيذ | R1: الميزانية (₪) | S1: نسبة الجاهزية % | T1: حالة الجاهزية | U1: التوصيات | V1: الموضوع | W1: الملاحظة | X1: مشكلة ميدانية | Y1: الإجراء المتخذ | Z1: تسمية التنفيذ | AA1: تسمية الجودة | AB1: تسمية الإغلاق | AC1: تسمية الخصم | AD1: المراقب | AE1: قيمة التنفيذ | AF1: قيمة الجودة | AG1: قيمة الإغلاق | AH1: قيمة الخصم | AI1: KPI | AJ1: التصنيف | AK1: الشهر | AL1: السنة | AM1: طريقة المراقبة | AN1: مرحلة المراقبة
A2: =IF(I2<>"",COUNTA($I$2:I2),"") -> 1 | B2: =IF(E2="","",CHOOSE(WEEKDAY(E2,2),"الاثنين","الثلاثاء","الأربعاء","الخميس","الجمعة","السبت","الأحد")) -> الأربعاء | C2: {=IF(E2="","",IF(M2<>"", M2&"/"&SUMPRODUCT((M$2:M2=M2)*1)&" - "&(ROW()-2), "إداري/"&SUMPRODUCT((M$2:M2="")*1)&" - "&(ROW()-2)))} -> إداري/1 - 0 | D2: =IF(AND(G2="",H2="",I2=""),"",IF(COUNTIFS(LISTS!$A$2:$A$67,G2,LISTS!$B$2:$B$67,H2,LISTS!$C$2:$C$67,I2)=0,"✗ هرم",IF(NOT(OR(Z2="ممتاز 100%",Z2="جيد 80%",Z2="مقبول 60%",Z2="خطر 40%",Z2="")),"✗ قائمة R",IF(NOT(OR(AA2="ممتاز 100%",AA2="جيد 85%",AA2="مقبول 70%",AA2="ضعيف 50%",AA2="")),"✗ قائمة S",IF(NOT(OR(AB2="مكتمل 100%",AB2="جزئي 60%",AB2="معلق 30%",AB2="مفتوح 0%",AB2="")),"✗ قائمة T",IF(NOT(OR(AC2="لا خصم 0",AC2="تأخير −5",AC2="عجز −10",AC2="جودة −15",AC2="امتثال −20",AC2="مخالفة −25",AC2="")),"✗ قائمة U",IF(AND(X2="لا",AC2<>"",AC2<>"لا خصم 0"),"✗ خصم",IF(AND(X2="نعم",AC2="لا خصم 0"),"✗ خصم",IF(AND(Z2="ممتاز 100%",AA2="ممتاز 100%",AB2<>"",AB2<>"مكتمل 100%"),"✗ إغلاق",IFERROR(IF(LEN(_xlfn.TEXTJOIN("، ",TRUE,IF(E2="","التاريخ",""),IF(F2="","الوقت",""),IF(G2="","المركز",""),IF(H2="","الدائرة",""),IF(I2="","القسم",""),IF(J2="","المسؤول",""),IF(K2="","نوع النشاط",""),IF(L2="","المشروع",""),IF(N2="","الممول",""),IF(V2="","الموضوع",""),IF(W2="","الملاحظة",""),IF(X2="","مشكلة",""),IF(Y2="","الإجراء",""),IF(Z2="","التنفيذ",""),IF(AA2="","الجودة",""),IF(AB2="","الإغلاق",""),IF(AC2="","الخصم",""),IF(AND(COUNTA($O2:$U2)>0,O2=""),"مدير المشروع",""),IF(AND(COUNTA($O2:$U2)>0,P2=""),"المستفيدين",""),IF(AND(COUNTA($O2:$U2)>0,Q2=""),"المناطق",""),IF(AND(COUNTA($O2:$U2)>0,R2=""),"الميزانية",""),IF(AND(COUNTA($O2:$U2)>0,S2=""),"نسبة الجاهزية",""),IF(AND(COUNTA($O2:$U2)>0,T2=""),"حالة الجاهزية",""),IF(AND(COUNTA($O2:$U2)>0,U2=""),"التوصيات","")))>0,"✗ ناقص: "&_xlfn.TEXTJOIN("، ",TRUE,IF(E2="","التاريخ",""),IF(F2="","الوقت",""),IF(G2="","المركز",""),IF(H2="","الدائرة",""),IF(I2="","القسم",""),IF(J2="","المسؤول",""),IF(K2="","نوع النشاط",""),IF(L2="","المشروع",""),IF(N2="","الممول",""),IF(V2="","الموضوع",""),IF(W2="","الملاحظة",""),IF(X2="","مشكلة",""),IF(Y2="","الإجراء",""),IF(Z2="","التنفيذ",""),IF(AA2="","الجودة",""),IF(AB2="","الإغلاق",""),IF(AC2="","الخصم",""),IF(AND(COUNTA($O2:$U2)>0,O2=""),"مدير المشروع",""),IF(AND(COUNTA($O2:$U2)>0,P2=""),"المستفيدين",""),IF(AND(COUNTA($O2:$U2)>0,Q2=""),"المناطق",""),IF(AND(COUNTA($O2:$U2)>0,R2=""),"الميزانية",""),IF(AND(COUNTA($O2:$U2)>0,S2=""),"نسبة الجاهزية",""),IF(AND(COUNTA($O2:$U2)>0,T2=""),"حالة الجاهزية",""),IF(AND(COUNTA($O2:$U2)>0,U2=""),"التوصيات","")),"✓"),"✓")))))))))) -> ✗ ناقص: الممول | E2: 46113 | F2: 0.39583333 | G2: الجمعية | H2: دائرة الاستثمار الخيري | I2: مطبخ الزيناتي / خارجي | J2: جهاد محمد محروس ابو الريش | K2: جودة خدمة | L2: الرغيف الخيري | V2: زيارة ميدانية مفاجئة لمخبز زادنا | W2: وُجد طحين قديم في المخزن استُخدم مما أثّر على جودة الخبز — تحذير نهائي لصاحب المخبز | X2: نعم | Y2: تحذير كتابي | Z2: مقبول 60% | AA2: ضعيف 50% | AB2: معلق 30% | AC2: جودة −15 | AD2: اياد أبو عبدو | AE2: =IFERROR(VLOOKUP(Z2,LISTS!$AL$2:$AM$1000,2,FALSE()),"") -> 60 | AF2: =IFERROR(VLOOKUP(AA2,LISTS!$AO$2:$AP$1000,2,FALSE()),"") -> 50 | AG2: =IFERROR(VLOOKUP(AB2,LISTS!$AR$2:$AS$1000,2,FALSE()),"") -> 30 | AH2: =IFERROR(VLOOKUP(AC2,LISTS!$AU$2:$AV$1000,2,FALSE()),"") -> 15 | AI2: =IF(OR(AE2="",AF2="",AG2=""),"—",IFERROR(ROUND(AE2*0.4+AF2*0.3+AG2*0.3-IF(ISNUMBER(AH2),AH2,0),1),"⚠️")) -> 33 | AJ2: =IF(AI2="—","—",IF(NOT(ISNUMBER(AI2)),"⚠️",IF(AI2>=98,"🌟 ممتاز جدًا",IF(AI2>=90,"⭐ ممتاز",IF(AI2>=75,"🟢 جيد",IF(AI2>=60,"🟡 مقبول",IF(AI2>=40,"🔴 ضعيف","🚨 خطر شديد"))))))) -> 🚨 خطر شديد | AK2: =IF(E2="","",MONTH(E2)) -> 4 | AL2: =IF(E2="","",YEAR(E2)) -> 2026
A3: =IF(I3<>"",COUNTA($I$2:I3),"") -> 2 | B3: =IF(E3="","",CHOOSE(WEEKDAY(E3,2),"الاثنين","الثلاثاء","الأربعاء","الخميس","الجمعة","السبت","الأحد")) -> الأربعاء | C3: {=IF(E3="","",IF(M3<>"", M3&"/"&SUMPRODUCT((M$2:M3=M3)*1)&" - "&(ROW()-2), "إداري/"&SUMPRODUCT((M$2:M3="")*1)&" - "&(ROW()-2)))} -> إداري/2 - 1 | D3: =IF(AND(G3="",H3="",I3=""),"",IF(COUNTIFS(LISTS!$A$2:$A$67,G3,LISTS!$B$2:$B$67,H3,LISTS!$C$2:$C$67,I3)=0,"✗ هرم",IF(NOT(OR(Z3="ممتاز 100%",Z3="جيد 80%",Z3="مقبول 60%",Z3="خطر 40%",Z3="")),"✗ قائمة R",IF(NOT(OR(AA3="ممتاز 100%",AA3="جيد 85%",AA3="مقبول 70%",AA3="ضعيف 50%",AA3="")),"✗ قائمة S",IF(NOT(OR(AB3="مكتمل 100%",AB3="جزئي 60%",AB3="معلق 30%",AB3="مفتوح 0%",AB3="")),"✗ قائمة T",IF(NOT(OR(AC3="لا خصم 0",AC3="تأخير −5",AC3="عجز −10",AC3="جودة −15",AC3="امتثال −20",AC3="مخالفة −25",AC3="")),"✗ قائمة U",IF(AND(X3="لا",AC3<>"",AC3<>"لا خصم 0"),"✗ خصم",IF(AND(X3="نعم",AC3="لا خصم 0"),"✗ خصم",IF(AND(Z3="ممتاز 100%",AA3="ممتاز 100%",AB3<>"",AB3<>"مكتمل 100%"),"✗ إغلاق",IFERROR(IF(LEN(_xlfn.TEXTJOIN("، ",TRUE,IF(E3="","التاريخ",""),IF(F3="","الوقت",""),IF(G3="","المركز",""),IF(H3="","الدائرة",""),IF(I3="","القسم",""),IF(J3="","المسؤول",""),IF(K3="","نوع النشاط",""),IF(L3="","المشروع",""),IF(N3="","الممول",""),IF(V3="","الموضوع",""),IF(W3="","الملاحظة",""),IF(X3="","مشكلة",""),IF(Y3="","الإجراء",""),IF(Z3="","التنفيذ",""),IF(AA3="","الجودة",""),IF(AB3="","الإغلاق",""),IF(AC3="","الخصم",""),IF(AND(COUNTA($O3:$U3)>0,O3=""),"مدير المشروع",""),IF(AND(COUNTA($O3:$U3)>0,P3=""),"المستفيدين",""),IF(AND(COUNTA($O3:$U3)>0,Q3=""),"المناطق",""),IF(AND(COUNTA($O3:$U3)>0,R3=""),"الميزانية",""),IF(AND(COUNTA($O3:$U3)>0,S3=""),"نسبة الجاهزية",""),IF(AND(COUNTA($O3:$U3)>0,T3=""),"حالة الجاهزية",""),IF(AND(COUNTA($O3:$U3)>0,U3=""),"التوصيات","")))>0,"✗ ناقص: "&_xlfn.TEXTJOIN("، ",TRUE,IF(E3="","التاريخ",""),IF(F3="","الوقت",""),IF(G3="","المركز",""),IF(H3="","الدائرة",""),IF(I3="","القسم",""),IF(J3="","المسؤول",""),IF(K3="","نوع النشاط",""),IF(L3="","المشروع",""),IF(N3="","الممول",""),IF(V3="","الموضوع",""),IF(W3="","الملاحظة",""),IF(X3="","مشكلة",""),IF(Y3="","الإجراء",""),IF(Z3="","التنفيذ",""),IF(AA3="","الجودة",""),IF(AB3="","الإغلاق",""),IF(AC3="","الخصم",""),IF(AND(COUNTA($O3:$U3)>0,O3=""),"مدير المشروع",""),IF(AND(COUNTA($O3:$U3)>0,P3=""),"المستفيدين",""),IF(AND(COUNTA($O3:$U3)>0,Q3=""),"المناطق",""),IF(AND(COUNTA($O3:$U3)>0,R3=""),"الميزانية",""),IF(AND(COUNTA($O3:$U3)>0,S3=""),"نسبة الجاهزية",""),IF(AND(COUNTA($O3:$U3)>0,T3=""),"حالة الجاهزية",""),IF(AND(COUNTA($O3:$U3)>0,U3=""),"التوصيات","")),"✓"),"✓")))))))))) -> ✗ ناقص: الممول | E3: 46113 | F3: 0.5 | G3: الجمعية | H3: دائرة الاستثمار الخيري | I3: مطبخ الزيناتي / خارجي | J3: جهاد محمد محروس ابو الريش | K3: جودة خدمة | L3: وجبات ساخنة | V3: متابعة وجبات مطبخ دار محسن رمضان — النصيرات (1 أبريل) | W3: 480 وجبة مفرد — الصالحي(160)، سلام(120)، الخطيب(140)،ابو محمود صالح(60) — تقييم ممتاز | X3: لا | Y3: مذكرة تذكيرية | Z3: ممتاز 100% | AA3: ممتاز 100% | AB3: مكتمل 100% | AC3: لا خصم 0 | AD3: سمير نصار | AE3: =IFERROR(VLOOKUP(Z3,LISTS!$AL$2:$AM$1000,2,FALSE()),"") -> 100 | AF3: =IFERROR(VLOOKUP(AA3,LISTS!$AO$2:$AP$1000,2,FALSE()),"") -> 100 | AG3: =IFERROR(VLOOKUP(AB3,LISTS!$AR$2:$AS$1000,2,FALSE()),"") -> 100 | AH3: =IFERROR(VLOOKUP(AC3,LISTS!$AU$2:$AV$1000,2,FALSE()),"") -> 0 | AI3: =IF(OR(AE3="",AF3="",AG3=""),"—",IFERROR(ROUND(AE3*0.4+AF3*0.3+AG3*0.3-IF(ISNUMBER(AH3),AH3,0),1),"⚠️")) -> 100 | AJ3: =IF(AI3="—","—",IF(NOT(ISNUMBER(AI3)),"⚠️",IF(AI3>=98,"🌟 ممتاز جدًا",IF(AI3>=90,"⭐ ممتاز",IF(AI3>=75,"🟢 جيد",IF(AI3>=60,"🟡 مقبول",IF(AI3>=40,"🔴 ضعيف","🚨 خطر شديد"))))))) -> 🌟 ممتاز جدًا | AK3: =IF(E3="","",MONTH(E3)) -> 4 | AL3: =IF(E3="","",YEAR(E3)) -> 2026
A4: =IF(I4<>"",COUNTA($I$2:I4),"") -> 3 | B4: =IF(E4="","",CHOOSE(WEEKDAY(E4,2),"الاثنين","الثلاثاء","الأربعاء","الخميس","الجمعة","السبت","الأحد")) -> الخميس | C4: {=IF(E4="","",IF(M4<>"", M4&"/"&SUMPRODUCT((M$2:M4=M4)*1)&" - "&(ROW()-2), "إداري/"&SUMPRODUCT((M$2:M4="")*1)&" - "&(ROW()-2)))} -> إداري/3 - 2 | D4: =IF(AND(G4="",H4="",I4=""),"",IF(COUNTIFS(LISTS!$A$2:$A$67,G4,LISTS!$B$2:$B$67,H4,LISTS!$C$2:$C$67,I4)=0,"✗ هرم",IF(NOT(OR(Z4="ممتاز 100%",Z4="جيد 80%",Z4="مقبول 60%",Z4="خطر 40%",Z4="")),"✗ قائمة R",IF(NOT(OR(AA4="ممتاز 100%",AA4="جيد 85%",AA4="مقبول 70%",AA4="ضعيف 50%",AA4="")),"✗ قائمة S",IF(NOT(OR(AB4="مكتمل 100%",AB4="جزئي 60%",AB4="معلق 30%",AB4="مفتوح 0%",AB4="")),"✗ قائمة T",IF(NOT(OR(AC4="لا خصم 0",AC4="تأخير −5",AC4="عجز −10",AC4="جودة −15",AC4="امتثال −20",AC4="مخالفة −25",AC4="")),"✗ قائمة U",IF(AND(X4="لا",AC4<>"",AC4<>"لا خصم 0"),"✗ خصم",IF(AND(X4="نعم",AC4="لا خصم 0"),"✗ خصم",IF(AND(Z4="ممتاز 100%",AA4="ممتاز 100%",AB4<>"",AB4<>"مكتمل 100%"),"✗ إغلاق",IFERROR(IF(LEN(_xlfn.TEXTJOIN("، ",TRUE,IF(E4="","التاريخ",""),IF(F4="","الوقت",""),IF(G4="","المركز",""),IF(H4="","الدائرة",""),IF(I4="","القسم",""),IF(J4="","المسؤول",""),IF(K4="","نوع النشاط",""),IF(L4="","المشروع",""),IF(N4="","الممول",""),IF(V4="","الموضوع",""),IF(W4="","الملاحظة",""),IF(X4="","مشكلة",""),IF(Y4="","الإجراء",""),IF(Z4="","التنفيذ",""),IF(AA4="","الجودة",""),IF(AB4="","الإغلاق",""),IF(AC4="","الخصم",""),IF(AND(COUNTA($O4:$U4)>0,O4=""),"مدير المشروع",""),IF(AND(COUNTA($O4:$U4)>0,P4=""),"المستفيدين",""),IF(AND(COUNTA($O4:$U4)>0,Q4=""),"المناطق",""),IF(AND(COUNTA($O4:$U4)>0,R4=""),"الميزانية",""),IF(AND(COUNTA($O4:$U4)>0,S4=""),"نسبة الجاهزية",""),IF(AND(COUNTA($O4:$U4)>0,T4=""),"حالة الجاهزية",""),IF(AND(COUNTA($O4:$U4)>0,U4=""),"التوصيات","")))>0,"✗ ناقص: "&_xlfn.TEXTJOIN("، ",TRUE,IF(E4="","التاريخ",""),IF(F4="","الوقت",""),IF(G4="","المركز",""),IF(H4="","الدائرة",""),IF(I4="","القسم",""),IF(J4="","المسؤول",""),IF(K4="","نوع النشاط",""),IF(L4="","المشروع",""),IF(N4="","الممول",""),IF(V4="","الموضوع",""),IF(W4="","الملاحظة",""),IF(X4="","مشكلة",""),IF(Y4="","الإجراء",""),IF(Z4="","التنفيذ",""),IF(AA4="","الجودة",""),IF(AB4="","الإغلاق",""),IF(AC4="","الخصم",""),IF(AND(COUNTA($O4:$U4)>0,O4=""),"مدير المشروع",""),IF(AND(COUNTA($O4:$U4)>0,P4=""),"المستفيدين",""),IF(AND(COUNTA($O4:$U4)>0,Q4=""),"المناطق",""),IF(AND(COUNTA($O4:$U4)>0,R4=""),"الميزانية",""),IF(AND(COUNTA($O4:$U4)>0,S4=""),"نسبة الجاهزية",""),IF(AND(COUNTA($O4:$U4)>0,T4=""),"حالة الجاهزية",""),IF(AND(COUNTA($O4:$U4)>0,U4=""),"التوصيات","")),"✓"),"✓")))))))))) -> ✗ ناقص: الممول | E4: 46114 | F4: 0.48958333 | G4: الجمعية | H4: دائرة المشاريع والتسويق والإعلام | I4: مكتب البريج | J4: محمود سالم هزاع القريناوي | K4: جودة خدمة | L4: وجبات ساخنة | V4: متابعة وجبات مطبخ دار محسن رمضان — البريج (2 أبريل) | W4: 480 وجبة مفرد (350ج رز+لحمة شقف) — النادي(150)، بلوك12(200)، البركس(50)، عزاءابو غليبة(30) — جودة جيد جداً | X4: لا | Y4: مذكرة تذكيرية | Z4: ممتاز 100% | AA4: جيد 85% | AB4: مكتمل 100% | AC4: لا خصم 0 | AD4: سمير نصار | AE4: =IFERROR(VLOOKUP(Z4,LISTS!$AL$2:$AM$1000,2,FALSE()),"") -> 100 | AF4: =IFERROR(VLOOKUP(AA4,LISTS!$AO$2:$AP$1000,2,FALSE()),"") -> 85 | AG4: =IFERROR(VLOOKUP(AB4,LISTS!$AR$2:$AS$1000,2,FALSE()),"") -> 100 | AH4: =IFERROR(VLOOKUP(AC4,LISTS!$AU$2:$AV$1000,2,FALSE()),"") -> 0 | AI4: =IF(OR(AE4="",AF4="",AG4=""),"—",IFERROR(ROUND(AE4*0.4+AF4*0.3+AG4*0.3-IF(ISNUMBER(AH4),AH4,0),1),"⚠️")) -> 95.5 | AJ4: =IF(AI4="—","—",IF(NOT(ISNUMBER(AI4)),"⚠️",IF(AI4>=98,"🌟 ممتاز جدًا",IF(AI4>=90,"⭐ ممتاز",IF(AI4>=75,"🟢 جيد",IF(AI4>=60,"🟡 مقبول",IF(AI4>=40,"🔴 ضعيف","🚨 خطر شديد"))))))) -> ⭐ ممتاز | AK4: =IF(E4="","",MONTH(E4)) -> 4 | AL4: =IF(E4="","",YEAR(E4)) -> 2026
A5: =IF(I5<>"",COUNTA($I$2:I5),"") -> 4 | B5: =IF(E5="","",CHOOSE(WEEKDAY(E5,2),"الاثنين","الثلاثاء","الأربعاء","الخميس","الجمعة","السبت","الأحد")) -> الخميس | C5: {=IF(E5="","",IF(M5<>"", M5&"/"&SUMPRODUCT((M$2:M5=M5)*1)&" - "&(ROW()-2), "إداري/"&SUMPRODUCT((M$2:M5="")*1)&" - "&(ROW()-2)))} -> إداري/4 - 3 | D5: =IF(AND(G5="",H5="",I5=""),"",IF(COUNTIFS(LISTS!$A$2:$A$67,G5,LISTS!$B$2:$B$67,H5,LISTS!$C$2:$C$67,I5)=0,"✗ هرم",IF(NOT(OR(Z5="ممتاز 100%",Z5="جيد 80%",Z5="مقبول 60%",Z5="خطر 40%",Z5="")),"✗ قائمة R",IF(NOT(OR(AA5="ممتاز 100%",AA5="جيد 85%",AA5="مقبول 70%",AA5="ضعيف 50%",AA5="")),"✗ قائمة S",IF(NOT(OR(AB5="مكتمل 100%",AB5="جزئي 60%",AB5="معلق 30%",AB5="مفتوح 0%",AB5="")),"✗ قائمة T",IF(NOT(OR(AC5="لا خصم 0",AC5="تأخير −5",AC5="عجز −10",AC5="جودة −15",AC5="امتثال −20",AC5="مخالفة −25",AC5="")),"✗ قائمة U",IF(AND(X5="لا",AC5<>"",AC5<>"لا خصم 0"),"✗ خصم",IF(AND(X5="نعم",AC5="لا خصم 0"),"✗ خصم",IF(AND(Z5="ممتاز 100%",AA5="ممتاز 100%",AB5<>"",AB5<>"مكتمل 100%"),"✗ إغلاق",IFERROR(IF(LEN(_xlfn.TEXTJOIN("، ",TRUE,IF(E5="","التاريخ",""),IF(F5="","الوقت",""),IF(G5="","المركز",""),IF(H5="","الدائرة",""),IF(I5="","القسم",""),IF(J5="","المسؤول",""),IF(K5="","نوع النشاط",""),IF(L5="","المشروع",""),IF(N5="","الممول",""),IF(V5="","الموضوع",""),IF(W5="","الملاحظة",""),IF(X5="","مشكلة",""),IF(Y5="","الإجراء",""),IF(Z5="","التنفيذ",""),IF(AA5="","الجودة",""),IF(AB5="","الإغلاق",""),IF(AC5="","الخصم",""),IF(AND(COUNTA($O5:$U5)>0,O5=""),"مدير المشروع",""),IF(AND(COUNTA($O5:$U5)>0,P5=""),"المستفيدين",""),IF(AND(COUNTA($O5:$U5)>0,Q5=""),"المناطق",""),IF(AND(COUNTA($O5:$U5)>0,R5=""),"الميزانية",""),IF(AND(COUNTA($O5:$U5)>0,S5=""),"نسبة الجاهزية",""),IF(AND(COUNTA($O5:$U5)>0,T5=""),"حالة الجاهزية",""),IF(AND(COUNTA($O5:$U5)>0,U5=""),"التوصيات","")))>0,"✗ ناقص: "&_xlfn.TEXTJOIN("، ",TRUE,IF(E5="","التاريخ",""),IF(F5="","الوقت",""),IF(G5="","المركز",""),IF(H5="","الدائرة",""),IF(I5="","القسم",""),IF(J5="","المسؤول",""),IF(K5="","نوع النشاط",""),IF(L5="","المشروع",""),IF(N5="","الممول",""),IF(V5="","الموضوع",""),IF(W5="","الملاحظة",""),IF(X5="","مشكلة",""),IF(Y5="","الإجراء",""),IF(Z5="","التنفيذ",""),IF(AA5="","الجودة",""),IF(AB5="","الإغلاق",""),IF(AC5="","الخصم",""),IF(AND(COUNTA($O5:$U5)>0,O5=""),"مدير المشروع",""),IF(AND(COUNTA($O5:$U5)>0,P5=""),"المستفيدين",""),IF(AND(COUNTA($O5:$U5)>0,Q5=""),"المناطق",""),IF(AND(COUNTA($O5:$U5)>0,R5=""),"الميزانية",""),IF(AND(COUNTA($O5:$U5)>0,S5=""),"نسبة الجاهزية",""),IF(AND(COUNTA($O5:$U5)>0,T5=""),"حالة الجاهزية",""),IF(AND(COUNTA($O5:$U5)>0,U5=""),"التوصيات","")),"✓"),"✓")))))))))) -> ✓ | E5: 46114 | F5: 0.50694444 | G5: الجمعية | H5: دائرة المشاريع والتسويق والإعلام | I5: مكتب خانيونس | J5: جهاد محمد محروس ابو الريش | K5: جودة خدمة | L5: وجبات ساخنة | N5: هيومن ابيل | V5: متابعة وجبات مطبخ الأخوة — خانيونس (2 أبريل) | W5: 3400 وجبة فردي (85ج لحمة+300ج رز) — ناصر(600)، الكويتي(300)، أطباء بلا حدود(200)، موظفو هيومن ابيل(500)، المتحابين(950)، جدار المتحابين(550)، بسمة أمل(300) — استلام 14:45، توزيع 16:00 — تقييم ممتاز | X5: لا | Y5: مذكرة تذكيرية | Z5: ممتاز 100% | AA5: ممتاز 100% | AB5: مكتمل 100% | AC5: لا خصم 0 | AD5: سمير نصار | AE5: =IFERROR(VLOOKUP(Z5,LISTS!$AL$2:$AM$1000,2,FALSE()),"") -> 100 | AF5: =IFERROR(VLOOKUP(AA5,LISTS!$AO$2:$AP$1000,2,FALSE()),"") -> 100 | AG5: =IFERROR(VLOOKUP(AB5,LISTS!$AR$2:$AS$1000,2,FALSE()),"") -> 100 | AH5: =IFERROR(VLOOKUP(AC5,LISTS!$AU$2:$AV$1000,2,FALSE()),"") -> 0 | AI5: =IF(OR(AE5="",AF5="",AG5=""),"—",IFERROR(ROUND(AE5*0.4+AF5*0.3+AG5*0.3-IF(ISNUMBER(AH5),AH5,0),1),"⚠️")) -> 100 | AJ5: =IF(AI5="—","—",IF(NOT(ISNUMBER(AI5)),"⚠️",IF(AI5>=98,"🌟 ممتاز جدًا",IF(AI5>=90,"⭐ ممتاز",IF(AI5>=75,"🟢 جيد",IF(AI5>=60,"🟡 مقبول",IF(AI5>=40,"🔴 ضعيف","🚨 خطر شديد"))))))) -> 🌟 ممتاز جدًا | AK5: =IF(E5="","",MONTH(E5)) -> 4 | AL5: =IF(E5="","",YEAR(E5)) -> 2026
A6: =IF(I6<>"",COUNTA($I$2:I6),"") -> 5 | B6: =IF(E6="","",CHOOSE(WEEKDAY(E6,2),"الاثنين","الثلاثاء","الأربعاء","الخميس","الجمعة","السبت","الأحد")) -> الخميس | C6: {=IF(E6="","",IF(M6<>"", M6&"/"&SUMPRODUCT((M$2:M6=M6)*1)&" - "&(ROW()-2), "إداري/"&SUMPRODUCT((M$2:M6="")*1)&" - "&(ROW()-2)))} -> إداري/5 - 4 | D6: =IF(AND(G6="",H6="",I6=""),"",IF(COUNTIFS(LISTS!$A$2:$A$67,G6,LISTS!$B$2:$B$67,H6,LISTS!$C$2:$C$67,I6)=0,"✗ هرم",IF(NOT(OR(Z6="ممتاز 100%",Z6="جيد 80%",Z6="مقبول 60%",Z6="خطر 40%",Z6="")),"✗ قائمة R",IF(NOT(OR(AA6="ممتاز 100%",AA6="جيد 85%",AA6="مقبول 70%",AA6="ضعيف 50%",AA6="")),"✗ قائمة S",IF(NOT(OR(AB6="مكتمل 100%",AB6="جزئي 60%",AB6="معلق 30%",AB6="مفتوح 0%",AB6="")),"✗ قائمة T",IF(NOT(OR(AC6="لا خصم 0",AC6="تأخير −5",AC6="عجز −10",AC6="جودة −15",AC6="امتثال −20",AC6="مخالفة −25",AC6="")),"✗ قائمة U",IF(AND(X6="لا",AC6<>"",AC6<>"لا خصم 0"),"✗ خصم",IF(AND(X6="نعم",AC6="لا خصم 0"),"✗ خصم",IF(AND(Z6="ممتاز 100%",AA6="ممتاز 100%",AB6<>"",AB6<>"مكتمل 100%"),"✗ إغلاق",IFERROR(IF(LEN(_xlfn.TEXTJOIN("، ",TRUE,IF(E6="","التاريخ",""),IF(F6="","الوقت",""),IF(G6="","المركز",""),IF(H6="","الدائرة",""),IF(I6="","القسم",""),IF(J6="","المسؤول",""),IF(K6="","نوع النشاط",""),IF(L6="","المشروع",""),IF(N6="","الممول",""),IF(V6="","الموضوع",""),IF(W6="","الملاحظة",""),IF(X6="","مشكلة",""),IF(Y6="","الإجراء",""),IF(Z6="","التنفيذ",""),IF(AA6="","الجودة",""),IF(AB6="","الإغلاق",""),IF(AC6="","الخصم",""),IF(AND(COUNTA($O6:$U6)>0,O6=""),"مدير المشروع",""),IF(AND(COUNTA($O6:$U6)>0,P6=""),"المستفيدين",""),IF(AND(COUNTA($O6:$U6)>0,Q6=""),"المناطق",""),IF(AND(COUNTA($O6:$U6)>0,R6=""),"الميزانية",""),IF(AND(COUNTA($O6:$U6)>0,S6=""),"نسبة الجاهزية",""),IF(AND(COUNTA($O6:$U6)>0,T6=""),"حالة الجاهزية",""),IF(AND(COUNTA($O6:$U6)>0,U6=""),"التوصيات","")))>0,"✗ ناقص: "&_xlfn.TEXTJOIN("، ",TRUE,IF(E6="","التاريخ",""),IF(F6="","الوقت",""),IF(G6="","المركز",""),IF(H6="","الدائرة",""),IF(I6="","القسم",""),IF(J6="","المسؤول",""),IF(K6="","نوع النشاط",""),IF(L6="","المشروع",""),IF(N6="","الممول",""),IF(V6="","الموضوع",""),IF(W6="","الملاحظة",""),IF(X6="","مشكلة",""),IF(Y6="","الإجراء",""),IF(Z6="","التنفيذ",""),IF(AA6="","الجودة",""),IF(AB6="","الإغلاق",""),IF(AC6="","الخصم",""),IF(AND(COUNTA($O6:$U6)>0,O6=""),"مدير المشروع",""),IF(AND(COUNTA($O6:$U6)>0,P6=""),"المستفيدين",""),IF(AND(COUNTA($O6:$U6)>0,Q6=""),"المناطق",""),IF(AND(COUNTA($O6:$U6)>0,R6=""),"الميزانية",""),IF(AND(COUNTA($O6:$U6)>0,S6=""),"نسبة الجاهزية",""),IF(AND(COUNTA($O6:$U6)>0,T6=""),"حالة الجاهزية",""),IF(AND(COUNTA($O6:$U6)>0,U6=""),"التوصيات","")),"✓"),"✓")))))))))) -> ✗ ناقص: الممول | E6: 46114 | F6: 0.45833333 | G6: الجمعية | H6: دائرة الاستثمار الخيري | I6: مطبخ الزيناتي / خارجي | J6: جهاد محمد محروس ابو الريش | K6: جودة خدمة | L6: وجبات ساخنة | V6: متابعة وجبات مطبخ دار محسن رمضان — البريج والنصيرات (2 أبريل) | W6: 480 وجبة مفرد — البريج(450)، النصيرات(30) — تقييم ممتاز | X6: لا | Y6: مذكرة تذكيرية | Z6: ممتاز 100% | AA6: ممتاز 100% | AB6: مكتمل 100% | AC6: لا خصم 0 | AD6: سمير نصار | AE6: =IFERROR(VLOOKUP(Z6,LISTS!$AL$2:$AM$1000,2,FALSE()),"") -> 100 | AF6: =IFERROR(VLOOKUP(AA6,LISTS!$AO$2:$AP$1000,2,FALSE()),"") -> 100 | AG6: =IFERROR(VLOOKUP(AB6,LISTS!$AR$2:$AS$1000,2,FALSE()),"") -> 100 | AH6: =IFERROR(VLOOKUP(AC6,LISTS!$AU$2:$AV$1000,2,FALSE()),"") -> 0 | AI6: =IF(OR(AE6="",AF6="",AG6=""),"—",IFERROR(ROUND(AE6*0.4+AF6*0.3+AG6*0.3-IF(ISNUMBER(AH6),AH6,0),1),"⚠️")) -> 100 | AJ6: =IF(AI6="—","—",IF(NOT(ISNUMBER(AI6)),"⚠️",IF(AI6>=98,"🌟 ممتاز جدًا",IF(AI6>=90,"⭐ ممتاز",IF(AI6>=75,"🟢 جيد",IF(AI6>=60,"🟡 مقبول",IF(AI6>=40,"🔴 ضعيف","🚨 خطر شديد"))))))) -> 🌟 ممتاز جدًا | AK6: =IF(E6="","",MONTH(E6)) -> 4 | AL6: =IF(E6="","",YEAR(E6)) -> 2026
A7: =IF(I7<>"",COUNTA($I$2:I7),"") -> 6 | B7: =IF(E7="","",CHOOSE(WEEKDAY(E7,2),"الاثنين","الثلاثاء","الأربعاء","الخميس","الجمعة","السبت","الأحد")) -> الجمعة | C7: {=IF(E7="","",IF(M7<>"", M7&"/"&SUMPRODUCT((M$2:M7=M7)*1)&" - "&(ROW()-2), "إداري/"&SUMPRODUCT((M$2:M7="")*1)&" - "&(ROW()-2)))} -> إداري/6 - 5 | D7: =IF(AND(G7="",H7="",I7=""),"",IF(COUNTIFS(LISTS!$A$2:$A$67,G7,LISTS!$B$2:$B$67,H7,LISTS!$C$2:$C$67,I7)=0,"✗ هرم",IF(NOT(OR(Z7="ممتاز 100%",Z7="جيد 80%",Z7="مقبول 60%",Z7="خطر 40%",Z7="")),"✗ قائمة R",IF(NOT(OR(AA7="ممتاز 100%",AA7="جيد 85%",AA7="مقبول 70%",AA7="ضعيف 50%",AA7="")),"✗ قائمة S",IF(NOT(OR(AB7="مكتمل 100%",AB7="جزئي 60%",AB7="معلق 30%",AB7="مفتوح 0%",AB7="")),"✗ قائمة T",IF(NOT(OR(AC7="لا خصم 0",AC7="تأخير −5",AC7="عجز −10",AC7="جودة −15",AC7="امتثال −20",AC7="مخالفة −25",AC7="")),"✗ قائمة U",IF(AND(X7="لا",AC7<>"",AC7<>"لا خصم 0"),"✗ خصم",IF(AND(X7="نعم",AC7="لا خصم 0"),"✗ خصم",IF(AND(Z7="ممتاز 100%",AA7="ممتاز 100%",AB7<>"",AB7<>"مكتمل 100%"),"✗ إغلاق",IFERROR(IF(LEN(_xlfn.TEXTJOIN("، ",TRUE,IF(E7="","التاريخ",""),IF(F7="","الوقت",""),IF(G7="","المركز",""),IF(H7="","الدائرة",""),IF(I7="","القسم",""),IF(J7="","المسؤول",""),IF(K7="","نوع النشاط",""),IF(L7="","المشروع",""),IF(N7="","الممول",""),IF(V7="","الموضوع",""),IF(W7="","الملاحظة",""),IF(X7="","مشكلة",""),IF(Y7="","الإجراء",""),IF(Z7="","التنفيذ",""),IF(AA7="","الجودة",""),IF(AB7="","الإغلاق",""),IF(AC7="","الخصم",""),IF(AND(COUNTA($O7:$U7)>0,O7=""),"مدير المشروع",""),IF(AND(COUNTA($O7:$U7)>0,P7=""),"المستفيدين",""),IF(AND(COUNTA($O7:$U7)>0,Q7=""),"المناطق",""),IF(AND(COUNTA($O7:$U7)>0,R7=""),"الميزانية",""),IF(AND(COUNTA($O7:$U7)>0,S7=""),"نسبة الجاهزية",""),IF(AND(COUNTA($O7:$U7)>0,T7=""),"حالة الجاهزية",""),IF(AND(COUNTA($O7:$U7)>0,U7=""),"التوصيات","")))>0,"✗ ناقص: "&_xlfn.TEXTJOIN("، ",TRUE,IF(E7="","التاريخ",""),IF(F7="","الوقت",""),IF(G7="","المركز",""),IF(H7="","الدائرة",""),IF(I7="","القسم",""),IF(J7="","المسؤول",""),IF(K7="","نوع النشاط",""),IF(L7="","المشروع",""),IF(N7="","الممول",""),IF(V7="","الموضوع",""),IF(W7="","الملاحظة",""),IF(X7="","مشكلة",""),IF(Y7="","الإجراء",""),IF(Z7="","التنفيذ",""),IF(AA7="","الجودة",""),IF(AB7="","الإغلاق",""),IF(AC7="","الخصم",""),IF(AND(COUNTA($O7:$U7)>0,O7=""),"مدير المشروع",""),IF(AND(COUNTA($O7:$U7)>0,P7=""),"المستفيدين",""),IF(AND(COUNTA($O7:$U7)>0,Q7=""),"المناطق",""),IF(AND(COUNTA($O7:$U7)>0,R7=""),"الميزانية",""),IF(AND(COUNTA($O7:$U7)>0,S7=""),"نسبة الجاهزية",""),IF(AND(COUNTA($O7:$U7)>0,T7=""),"حالة الجاهزية",""),IF(AND(COUNTA($O7:$U7)>0,U7=""),"التوصيات","")),"✓"),"✓")))))))))) -> ✗ ناقص: الممول | E7: 46115 | F7: 0.5 | G7: الجمعية | H7: دائرة المشاريع والتسويق والإعلام | I7: مكتب المغازي | J7: طارق حسن ع.القادر قنديل | K7: جودة خدمة | L7: وجبات ساخنة | V7: متابعة وجبات مطبخ دار محسن رمضان — المغازي (3 أبريل) | W7: 480 وجبة مفرد (350ج رز+لحمة) — بركة الوز وحارة القساطنة والمهاجرين — تقييم ممتاز | X7: لا | Y7: مذكرة تذكيرية | Z7: ممتاز 100% | AA7: ممتاز 100% | AB7: مكتمل 100% | AC7: لا خصم 0 | AD7: سمير نصار | AE7: =IFERROR(VLOOKUP(Z7,LISTS!$AL$2:$AM$1000,2,FALSE()),"") -> 100 | AF7: =IFERROR(VLOOKUP(AA7,LISTS!$AO$2:$AP$1000,2,FALSE()),"") -> 100 | AG7: =IFERROR(VLOOKUP(AB7,LISTS!$AR$2:$AS$1000,2,FALSE()),"") -> 100 | AH7: =IFERROR(VLOOKUP(AC7,LISTS!$AU$2:$AV$1000,2,FALSE()),"") -> 0 | AI7: =IF(OR(AE7="",AF7="",AG7=""),"—",IFERROR(ROUND(AE7*0.4+AF7*0.3+AG7*0.3-IF(ISNUMBER(AH7),AH7,0),1),"⚠️")) -> 100 | AJ7: =IF(AI7="—","—",IF(NOT(ISNUMBER(AI7)),"⚠️",IF(AI7>=98,"🌟 ممتاز جدًا",IF(AI7>=90,"⭐ ممتاز",IF(AI7>=75,"🟢 جيد",IF(AI7>=60,"🟡 مقبول",IF(AI7>=40,"🔴 ضعيف","🚨 خطر شديد"))))))) -> 🌟 ممتاز جدًا | AK7: =IF(E7="","",MONTH(E7)) -> 4 | AL7: =IF(E7="","",YEAR(E7)) -> 2026
A8: =IF(I8<>"",COUNTA($I$2:I8),"") -> 7 | B8: =IF(E8="","",CHOOSE(WEEKDAY(E8,2),"الاثنين","الثلاثاء","الأربعاء","الخميس","الجمعة","السبت","الأحد")) -> الجمعة | C8: {=IF(E8="","",IF(M8<>"", M8&"/"&SUMPRODUCT((M$2:M8=M8)*1)&" - "&(ROW()-2), "إداري/"&SUMPRODUCT((M$2:M8="")*1)&" - "&(ROW()-2)))} -> إداري/7 - 6 | D8: =IF(AND(G8="",H8="",I8=""),"",IF(COUNTIFS(LISTS!$A$2:$A$67,G8,LISTS!$B$2:$B$67,H8,LISTS!$C$2:$C$67,I8)=0,"✗ هرم",IF(NOT(OR(Z8="ممتاز 100%",Z8="جيد 80%",Z8="مقبول 60%",Z8="خطر 40%",Z8="")),"✗ قائمة R",IF(NOT(OR(AA8="ممتاز 100%",AA8="جيد 85%",AA8="مقبول 70%",AA8="ضعيف 50%",AA8="")),"✗ قائمة S",IF(NOT(OR(AB8="مكتمل 100%",AB8="جزئي 60%",AB8="معلق 30%",AB8="مفتوح 0%",AB8="")),"✗ قائمة T",IF(NOT(OR(AC8="لا خصم 0",AC8="تأخير −5",AC8="عجز −10",AC8="جودة −15",AC8="امتثال −20",AC8="مخالفة −25",AC8="")),"✗ قائمة U",IF(AND(X8="لا",AC8<>"",AC8<>"لا خصم 0"),"✗ خصم",IF(AND(X8="نعم",AC8="لا خصم 0"),"✗ خصم",IF(AND(Z8="ممتاز 100%",AA8="ممتاز 100%",AB8<>"",AB8<>"مكتمل 100%"),"✗ إغلاق",IFERROR(IF(LEN(_xlfn.TEXTJOIN("، ",TRUE,IF(E8="","التاريخ",""),IF(F8="","الوقت",""),IF(G8="","المركز",""),IF(H8="","الدائرة",""),IF(I8="","القسم",""),IF(J8="","المسؤول",""),IF(K8="","نوع النشاط",""),IF(L8="","المشروع",""),IF(N8="","الممول",""),IF(V8="","الموضوع",""),IF(W8="","الملاحظة",""),IF(X8="","مشكلة",""),IF(Y8="","الإجراء",""),IF(Z8="","التنفيذ",""),IF(AA8="","الجودة",""),IF(AB8="","الإغلاق",""),IF(AC8="","الخصم",""),IF(AND(COUNTA($O8:$U8)>0,O8=""),"مدير المشروع",""),IF(AND(COUNTA($O8:$U8)>0,P8=""),"المستفيدين",""),IF(AND(COUNTA($O8:$U8)>0,Q8=""),"المناطق",""),IF(AND(COUNTA($O8:$U8)>0,R8=""),"الميزانية",""),IF(AND(COUNTA($O8:$U8)>0,S8=""),"نسبة الجاهزية",""),IF(AND(COUNTA($O8:$U8)>0,T8=""),"حالة الجاهزية",""),IF(AND(COUNTA($O8:$U8)>0,U8=""),"التوصيات","")))>0,"✗ ناقص: "&_xlfn.TEXTJOIN("، ",TRUE,IF(E8="","التاريخ",""),IF(F8="","الوقت",""),IF(G8="","المركز",""),IF(H8="","الدائرة",""),IF(I8="","القسم",""),IF(J8="","المسؤول",""),IF(K8="","نوع النشاط",""),IF(L8="","المشروع",""),IF(N8="","الممول",""),IF(V8="","الموضوع",""),IF(W8="","الملاحظة",""),IF(X8="","مشكلة",""),IF(Y8="","الإجراء",""),IF(Z8="","التنفيذ",""),IF(AA8="","الجودة",""),IF(AB8="","الإغلاق",""),IF(AC8="","الخصم",""),IF(AND(COUNTA($O8:$U8)>0,O8=""),"مدير المشروع",""),IF(AND(COUNTA($O8:$U8)>0,P8=""),"المستفيدين",""),IF(AND(COUNTA($O8:$U8)>0,Q8=""),"المناطق",""),IF(AND(COUNTA($O8:$U8)>0,R8=""),"الميزانية",""),IF(AND(COUNTA($O8:$U8)>0,S8=""),"نسبة الجاهزية",""),IF(AND(COUNTA($O8:$U8)>0,T8=""),"حالة الجاهزية",""),IF(AND(COUNTA($O8:$U8)>0,U8=""),"التوصيات","")),"✓"),"✓")))))))))) -> ✗ ناقص: الممول | E8: 46115 | F8: 0.45833333 | G8: الجمعية | H8: دائرة الاستثمار الخيري | I8: مطبخ الزيناتي / خارجي | J8: جهاد محمد محروس ابو الريش | K8: جودة خدمة | L8: وجبات ساخنة | V8: متابعة وجبات مطبخ دار محسن رمضان — المغازي والنصيرات (3 أبريل) | W8: 480 وجبة مفرد — المغازي(450)، النصيرات(30) — تقييم ممتاز | X8: لا | Y8: مذكرة تذكيرية | Z8: ممتاز 100% | AA8: ممتاز 100% | AB8: مكتمل 100% | AC8: لا خصم 0 | AD8: سمير نصار | AE8: =IFERROR(VLOOKUP(Z8,LISTS!$AL$2:$AM$1000,2,FALSE()),"") -> 100 | AF8: =IFERROR(VLOOKUP(AA8,LISTS!$AO$2:$AP$1000,2,FALSE()),"") -> 100 | AG8: =IFERROR(VLOOKUP(AB8,LISTS!$AR$2:$AS$1000,2,FALSE()),"") -> 100 | AH8: =IFERROR(VLOOKUP(AC8,LISTS!$AU$2:$AV$1000,2,FALSE()),"") -> 0 | AI8: =IF(OR(AE8="",AF8="",AG8=""),"—",IFERROR(ROUND(AE8*0.4+AF8*0.3+AG8*0.3-IF(ISNUMBER(AH8),AH8,0),1),"⚠️")) -> 100 | AJ8: =IF(AI8="—","—",IF(NOT(ISNUMBER(AI8)),"⚠️",IF(AI8>=98,"🌟 ممتاز جدًا",IF(AI8>=90,"⭐ ممتاز",IF(AI8>=75,"🟢 جيد",IF(AI8>=60,"🟡 مقبول",IF(AI8>=40,"🔴 ضعيف","🚨 خطر شديد"))))))) -> 🌟 ممتاز جدًا | AK8: =IF(E8="","",MONTH(E8)) -> 4 | AL8: =IF(E8="","",YEAR(E8)) -> 2026
A9: =IF(I9<>"",COUNTA($I$2:I9),"") -> 8 | B9: =IF(E9="","",CHOOSE(WEEKDAY(E9,2),"الاثنين","الثلاثاء","الأربعاء","الخميس","الجمعة","السبت","الأحد")) -> السبت | C9: {=IF(E9="","",IF(M9<>"", M9&"/"&SUMPRODUCT((M$2:M9=M9)*1)&" - "&(ROW()-2), "إداري/"&SUMPRODUCT((M$2:M9="")*1)&" - "&(ROW()-2)))} -> إداري/8 - 7 | D9: =IF(AND(G9="",H9="",I9=""),"",IF(COUNTIFS(LISTS!$A$2:$A$67,G9,LISTS!$B$2:$B$67,H9,LISTS!$C$2:$C$67,I9)=0,"✗ هرم",IF(NOT(OR(Z9="ممتاز 100%",Z9="جيد 80%",Z9="مقبول 60%",Z9="خطر 40%",Z9="")),"✗ قائمة R",IF(NOT(OR(AA9="ممتاز 100%",AA9="جيد 85%",AA9="مقبول 70%",AA9="ضعيف 50%",AA9="")),"✗ قائمة S",IF(NOT(OR(AB9="مكتمل 100%",AB9="جزئي 60%",AB9="معلق 30%",AB9="مفتوح 0%",AB9="")),"✗ قائمة T",IF(NOT(OR(AC9="لا خصم 0",AC9="تأخير −5",AC9="عجز −10",AC9="جودة −15",AC9="امتثال −20",AC9="مخالفة −25",AC9="")),"✗ قائمة U",IF(AND(X9="لا",AC9<>"",AC9<>"لا خصم 0"),"✗ خصم",IF(AND(X9="نعم",AC9="لا خصم 0"),"✗ خصم",IF(AND(Z9="ممتاز 100%",AA9="ممتاز 100%",AB9<>"",AB9<>"مكتمل 100%"),"✗ إغلاق",IFERROR(IF(LEN(_xlfn.TEXTJOIN("، ",TRUE,IF(E9="","التاريخ",""),IF(F9="","الوقت",""),IF(G9="","المركز",""),IF(H9="","الدائرة",""),IF(I9="","القسم",""),IF(J9="","المسؤول",""),IF(K9="","نوع النشاط",""),IF(L9="","المشروع",""),IF(N9="","الممول",""),IF(V9="","الموضوع",""),IF(W9="","الملاحظة",""),IF(X9="","مشكلة",""),IF(Y9="","الإجراء",""),IF(Z9="","التنفيذ",""),IF(AA9="","الجودة",""),IF(AB9="","الإغلاق",""),IF(AC9="","الخصم",""),IF(AND(COUNTA($O9:$U9)>0,O9=""),"مدير المشروع",""),IF(AND(COUNTA($O9:$U9)>0,P9=""),"المستفيدين",""),IF(AND(COUNTA($O9:$U9)>0,Q9=""),"المناطق",""),IF(AND(COUNTA($O9:$U9)>0,R9=""),"الميزانية",""),IF(AND(COUNTA($O9:$U9)>0,S9=""),"نسبة الجاهزية",""),IF(AND(COUNTA($O9:$U9)>0,T9=""),"حالة الجاهزية",""),IF(AND(COUNTA($O9:$U9)>0,U9=""),"التوصيات","")))>0,"✗ ناقص: "&_xlfn.TEXTJOIN("، ",TRUE,IF(E9="","التاريخ",""),IF(F9="","الوقت",""),IF(G9="","المركز",""),IF(H9="","الدائرة",""),IF(I9="","القسم",""),IF(J9="","المسؤول",""),IF(K9="","نوع النشاط",""),IF(L9="","المشروع",""),IF(N9="","الممول",""),IF(V9="","الموضوع",""),IF(W9="","الملاحظة",""),IF(X9="","مشكلة",""),IF(Y9="","الإجراء",""),IF(Z9="","التنفيذ",""),IF(AA9="","الجودة",""),IF(AB9="","الإغلاق",""),IF(AC9="","الخصم",""),IF(AND(COUNTA($O9:$U9)>0,O9=""),"مدير المشروع",""),IF(AND(COUNTA($O9:$U9)>0,P9=""),"المستفيدين",""),IF(AND(COUNTA($O9:$U9)>0,Q9=""),"المناطق",""),IF(AND(COUNTA($O9:$U9)>0,R9=""),"الميزانية",""),IF(AND(COUNTA($O9:$U9)>0,S9=""),"نسبة الجاهزية",""),IF(AND(COUNTA($O9:$U9)>0,T9=""),"حالة الجاهزية",""),IF(AND(COUNTA($O9:$U9)>0,U9=""),"التوصيات","")),"✓"),"✓")))))))))) -> ✓ | E9: 46116 | F9: 0.5625 | G9: الجمعية | H9: دائرة المشاريع والتسويق والإعلام | I9: مكتب خانيونس | J9: جهاد محمد محروس ابو الريش | K9: جودة خدمة | L9: وجبات ساخنة | N9: هيومن ابيل | V9: متابعة وجبات مطبخ الأخوة — خانيونس (4 أبريل) | W9: 3400 وجبة فردي (85ج لحمة+300ج رز) — ناصر(600)، الكويتي(300)، أطباء بلا حدود(200)، السلطان(550)، الشهم(400)، المستقبل(600)، شريان الحياة(750) — استلام 13:30، توزيع 15:15 — ملاحظة: تأخير من المطبخ | X9: نعم | Y9: إشعار رسمي | Z9: ممتاز 100% | AA9: ممتاز 100% | AB9: مكتمل 100% | AC9: تأخير −5 | AD9: سمير نصار | AE9: =IFERROR(VLOOKUP(Z9,LISTS!$AL$2:$AM$1000,2,FALSE()),"") -> 100 | AF9: =IFERROR(VLOOKUP(AA9,LISTS!$AO$2:$AP$1000,2,FALSE()),"") -> 100 | AG9: =IFERROR(VLOOKUP(AB9,LISTS!$AR$2:$AS$1000,2,FALSE()),"") -> 100 | AH9: =IFERROR(VLOOKUP(AC9,LISTS!$AU$2:$AV$1000,2,FALSE()),"") -> 5 | AI9: =IF(OR(AE9="",AF9="",AG9=""),"—",IFERROR(ROUND(AE9*0.4+AF9*0.3+AG9*0.3-IF(ISNUMBER(AH9),AH9,0),1),"⚠️")) -> 95 | AJ9: =IF(AI9="—","—",IF(NOT(ISNUMBER(AI9)),"⚠️",IF(AI9>=98,"🌟 ممتاز جدًا",IF(AI9>=90,"⭐ ممتاز",IF(AI9>=75,"🟢 جيد",IF(AI9>=60,"🟡 مقبول",IF(AI9>=40,"🔴 ضعيف","🚨 خطر شديد"))))))) -> ⭐ ممتاز | AK9: =IF(E9="","",MONTH(E9)) -> 4 | AL9: =IF(E9="","",YEAR(E9)) -> 2026
A10: =IF(I10<>"",COUNTA($I$2:I10),"") -> 9 | B10: =IF(E10="","",CHOOSE(WEEKDAY(E10,2),"الاثنين","الثلاثاء","الأربعاء","الخميس","الجمعة","السبت","الأحد")) -> الأربعاء | C10: توزيع الوجبات الغذائية | D10: =IF(AND(G10="",H10="",I10=""),"",IF(COUNTIFS(LISTS!$A$2:$A$67,G10,LISTS!$B$2:$B$67,H10,LISTS!$C$2:$C$67,I10)=0,"✗ هرم",IF(NOT(OR(Z10="ممتاز 100%",Z10="جيد 80%",Z10="مقبول 60%",Z10="خطر 40%",Z10="")),"✗ قائمة R",IF(NOT(OR(AA10="ممتاز 100%",AA10="جيد 85%",AA10="مقبول 70%",AA10="ضعيف 50%",AA10="")),"✗ قائمة S",IF(NOT(OR(AB10="مكتمل 100%",AB10="جزئي 60%",AB10="معلق 30%",AB10="مفتوح 0%",AB10="")),"✗ قائمة T",IF(NOT(OR(AC10="لا خصم 0",AC10="تأخير −5",AC10="عجز −10",AC10="جودة −15",AC10="امتثال −20",AC10="مخالفة −25",AC10="")),"✗ قائمة U",IF(AND(X10="لا",AC10<>"",AC10<>"لا خصم 0"),"✗ خصم",IF(AND(X10="نعم",AC10="لا خصم 0"),"✗ خصم",IF(AND(Z10="ممتاز 100%",AA10="ممتاز 100%",AB10<>"",AB10<>"مكتمل 100%"),"✗ إغلاق",IFERROR(IF(LEN(_xlfn.TEXTJOIN("، ",TRUE,IF(E10="","التاريخ",""),IF(F10="","الوقت",""),IF(G10="","المركز",""),IF(H10="","الدائرة",""),IF(I10="","القسم",""),IF(J10="","المسؤول",""),IF(K10="","نوع النشاط",""),IF(L10="","المشروع",""),IF(N10="","الممول",""),IF(V10="","الموضوع",""),IF(W10="","الملاحظة",""),IF(X10="","مشكلة",""),IF(Y10="","الإجراء",""),IF(Z10="","التنفيذ",""),IF(AA10="","الجودة",""),IF(AB10="","الإغلاق",""),IF(AC10="","الخصم",""),IF(AND(COUNTA($O10:$U10)>0,O10=""),"مدير المشروع",""),IF(AND(COUNTA($O10:$U10)>0,P10=""),"المستفيدين",""),IF(AND(COUNTA($O10:$U10)>0,Q10=""),"المناطق",""),IF(AND(COUNTA($O10:$U10)>0,R10=""),"الميزانية",""),IF(AND(COUNTA($O10:$U10)>0,S10=""),"نسبة الجاهزية",""),IF(AND(COUNTA($O10:$U10)>0,T10=""),"حالة الجاهزية",""),IF(AND(COUNTA($O10:$U10)>0,U10=""),"التوصيات","")))>0,"✗ ناقص: "&_xlfn.TEXTJOIN("، ",TRUE,IF(E10="","التاريخ",""),IF(F10="","الوقت",""),IF(G10="","المركز",""),IF(H10="","الدائرة",""),IF(I10="","القسم",""),IF(J10="","المسؤول",""),IF(K10="","نوع النشاط",""),IF(L10="","المشروع",""),IF(N10="","الممول",""),IF(V10="","الموضوع",""),IF(W10="","الملاحظة",""),IF(X10="","مشكلة",""),IF(Y10="","الإجراء",""),IF(Z10="","التنفيذ",""),IF(AA10="","الجودة",""),IF(AB10="","الإغلاق",""),IF(AC10="","الخصم",""),IF(AND(COUNTA($O10:$U10)>0,O10=""),"مدير المشروع",""),IF(AND(COUNTA($O10:$U10)>0,P10=""),"المستفيدين",""),IF(AND(COUNTA($O10:$U10)>0,Q10=""),"المناطق",""),IF(AND(COUNTA($O10:$U10)>0,R10=""),"الميزانية",""),IF(AND(COUNTA($O10:$U10)>0,S10=""),"نسبة الجاهزية",""),IF(AND(COUNTA($O10:$U10)>0,T10=""),"حالة الجاهزية",""),IF(AND(COUNTA($O10:$U10)>0,U10=""),"التوصيات","")),"✓"),"✓")))))))))) -> ✗ هرم | E10: 46120 | F10: 0.39583333 | G10: رقم ونوع المشروع | H10: دائرة المشاريع والتسويق والإعلام | I10: غذائي/912 | K10: فحص سلامة | L10: متابعة السيارات | V10: فحص سيارة تويوتا | W10: فحص زيت ومياه وتدقيق كشف حركة السيارة — سير طبيعي | X10: لا | Y10: مذكرة تذكيرية | Z10: ممتاز 100% | AA10: ممتاز 100% | AB10: مكتمل 100% | AC10: لا خصم 0 | AD10: اياد أبو عبدو | AE10: =IFERROR(VLOOKUP(Z10,LISTS!$AL$2:$AM$1000,2,FALSE()),"") -> 100 | AF10: =IFERROR(VLOOKUP(AA10,LISTS!$AO$2:$AP$1000,2,FALSE()),"") -> 100 | AG10: =IFERROR(VLOOKUP(AB10,LISTS!$AR$2:$AS$1000,2,FALSE()),"") -> 100 | AH10: =IFERROR(VLOOKUP(AC10,LISTS!$AU$2:$AV$1000,2,FALSE()),"") -> 0 | AI10: =IF(OR(AE10="",AF10="",AG10=""),"—",IFERROR(ROUND(AE10*0.4+AF10*0.3+AG10*0.3-IF(ISNUMBER(AH10),AH10,0),1),"⚠️")) -> 100 | AJ10: =IF(AI10="—","—",IF(NOT(ISNUMBER(AI10)),"⚠️",IF(AI10>=98,"🌟 ممتاز جدًا",IF(AI10>=90,"⭐ ممتاز",IF(AI10>=75,"🟢 جيد",IF(AI10>=60,"🟡 مقبول",IF(AI10>=40,"🔴 ضعيف","🚨 خطر شديد"))))))) -> 🌟 ممتاز جدًا | AK10: =IF(E10="","",MONTH(E10)) -> 4 | AL10: =IF(E10="","",YEAR(E10)) -> 2026
A11: =IF(I11<>"",COUNTA($I$2:I11),"") -> 10 | B11: =IF(E11="","",CHOOSE(WEEKDAY(E11,2),"الاثنين","الثلاثاء","الأربعاء","الخميس","الجمعة","السبت","الأحد")) -> الأربعاء | C11: بريدجز لوجيستيكس انترناشونال | D11: =IF(AND(G11="",H11="",I11=""),"",IF(COUNTIFS(LISTS!$A$2:$A$67,G11,LISTS!$B$2:$B$67,H11,LISTS!$C$2:$C$67,I11)=0,"✗ هرم",IF(NOT(OR(Z11="ممتاز 100%",Z11="جيد 80%",Z11="مقبول 60%",Z11="خطر 40%",Z11="")),"✗ قائمة R",IF(NOT(OR(AA11="ممتاز 100%",AA11="جيد 85%",AA11="مقبول 70%",AA11="ضعيف 50%",AA11="")),"✗ قائمة S",IF(NOT(OR(AB11="مكتمل 100%",AB11="جزئي 60%",AB11="معلق 30%",AB11="مفتوح 0%",AB11="")),"✗ قائمة T",IF(NOT(OR(AC11="لا خصم 0",AC11="تأخير −5",AC11="عجز −10",AC11="جودة −15",AC11="امتثال −20",AC11="مخالفة −25",AC11="")),"✗ قائمة U",IF(AND(X11="لا",AC11<>"",AC11<>"لا خصم 0"),"✗ خصم",IF(AND(X11="نعم",AC11="لا خصم 0"),"✗ خصم",IF(AND(Z11="ممتاز 100%",AA11="ممتاز 100%",AB11<>"",AB11<>"مكتمل 100%"),"✗ إغلاق",IFERROR(IF(LEN(_xlfn.TEXTJOIN("، ",TRUE,IF(E11="","التاريخ",""),IF(F11="","الوقت",""),IF(G11="","المركز",""),IF(H11="","الدائرة",""),IF(I11="","القسم",""),IF(J11="","المسؤول",""),IF(K11="","نوع النشاط",""),IF(L11="","المشروع",""),IF(N11="","الممول",""),IF(V11="","الموضوع",""),IF(W11="","الملاحظة",""),IF(X11="","مشكلة",""),IF(Y11="","الإجراء",""),IF(Z11="","التنفيذ",""),IF(AA11="","الجودة",""),IF(AB11="","الإغلاق",""),IF(AC11="","الخصم",""),IF(AND(COUNTA($O11:$U11)>0,O11=""),"مدير المشروع",""),IF(AND(COUNTA($O11:$U11)>0,P11=""),"المستفيدين",""),IF(AND(COUNTA($O11:$U11)>0,Q11=""),"المناطق",""),IF(AND(COUNTA($O11:$U11)>0,R11=""),"الميزانية",""),IF(AND(COUNTA($O11:$U11)>0,S11=""),"نسبة الجاهزية",""),IF(AND(COUNTA($O11:$U11)>0,T11=""),"حالة الجاهزية",""),IF(AND(COUNTA($O11:$U11)>0,U11=""),"التوصيات","")))>0,"✗ ناقص: "&_xlfn.TEXTJOIN("، ",TRUE,IF(E11="","التاريخ",""),IF(F11="","الوقت",""),IF(G11="","المركز",""),IF(H11="","الدائرة",""),IF(I11="","القسم",""),IF(J11="","المسؤول",""),IF(K11="","نوع النشاط",""),IF(L11="","المشروع",""),IF(N11="","الممول",""),IF(V11="","الموضوع",""),IF(W11="","الملاحظة",""),IF(X11="","مشكلة",""),IF(Y11="","الإجراء",""),IF(Z11="","التنفيذ",""),IF(AA11="","الجودة",""),IF(AB11="","الإغلاق",""),IF(AC11="","الخصم",""),IF(AND(COUNTA($O11:$U11)>0,O11=""),"مدير المشروع",""),IF(AND(COUNTA($O11:$U11)>0,P11=""),"المستفيدين",""),IF(AND(COUNTA($O11:$U11)>0,Q11=""),"المناطق",""),IF(AND(COUNTA($O11:$U11)>0,R11=""),"الميزانية",""),IF(AND(COUNTA($O11:$U11)>0,S11=""),"نسبة الجاهزية",""),IF(AND(COUNTA($O11:$U11)>0,T11=""),"حالة الجاهزية",""),IF(AND(COUNTA($O11:$U11)>0,U11=""),"التوصيات","")),"✓"),"✓")))))))))) -> ✗ هرم | E11: 46120 | F11: 0.39583333 | G11: مندوب المشتريات | H11: دائرة المشاريع والتسويق والإعلام | I11: هاني رمانة | K11: فحص سلامة | L11: متابعة السيارات | V11: فحص سيارة كرافت | W11: فحص زيت ومياه وتدقيق كشف حركة السيارة — سير طبيعي | X11: لا | Y11: مذكرة تذكيرية | Z11: ممتاز 100% | AA11: ممتاز 100% | AB11: مكتمل 100% | AC11: لا خصم 0 | AD11: اياد أبو عبدو | AE11: =IFERROR(VLOOKUP(Z11,LISTS!$AL$2:$AM$1000,2,FALSE()),"") -> 100 | AF11: =IFERROR(VLOOKUP(AA11,LISTS!$AO$2:$AP$1000,2,FALSE()),"") -> 100 | AG11: =IFERROR(VLOOKUP(AB11,LISTS!$AR$2:$AS$1000,2,FALSE()),"") -> 100 | AH11: =IFERROR(VLOOKUP(AC11,LISTS!$AU$2:$AV$1000,2,FALSE()),"") -> 0 | AI11: =IF(OR(AE11="",AF11="",AG11=""),"—",IFERROR(ROUND(AE11*0.4+AF11*0.3+AG11*0.3-IF(ISNUMBER(AH11),AH11,0),1),"⚠️")) -> 100 | AJ11: =IF(AI11="—","—",IF(NOT(ISNUMBER(AI11)),"⚠️",IF(AI11>=98,"🌟 ممتاز جدًا",IF(AI11>=90,"⭐ ممتاز",IF(AI11>=75,"🟢 جيد",IF(AI11>=60,"🟡 مقبول",IF(AI11>=40,"🔴 ضعيف","🚨 خطر شديد"))))))) -> 🌟 ممتاز جدًا | AK11: =IF(E11="","",MONTH(E11)) -> 4 | AL11: =IF(E11="","",YEAR(E11)) -> 2026
A12: =IF(I12<>"",COUNTA($I$2:I12),"") -> 11 | B12: =IF(E12="","",CHOOSE(WEEKDAY(E12,2),"الاثنين","الثلاثاء","الأربعاء","الخميس","الجمعة","السبت","الأحد")) -> الأربعاء | C12: فاطمة عرمانة | D12: =IF(AND(G12="",H12="",I12=""),"",IF(COUNTIFS(LISTS!$A$2:$A$67,G12,LISTS!$B$2:$B$67,H12,LISTS!$C$2:$C$67,I12)=0,"✗ هرم",IF(NOT(OR(Z12="ممتاز 100%",Z12="جيد 80%",Z12="مقبول 60%",Z12="خطر 40%",Z12="")),"✗ قائمة R",IF(NOT(OR(AA12="ممتاز 100%",AA12="جيد 85%",AA12="مقبول 70%",AA12="ضعيف 50%",AA12="")),"✗ قائمة S",IF(NOT(OR(AB12="مكتمل 100%",AB12="جزئي 60%",AB12="معلق 30%",AB12="مفتوح 0%",AB12="")),"✗ قائمة T",IF(NOT(OR(AC12="لا خصم 0",AC12="تأخير −5",AC12="عجز −10",AC12="جودة −15",AC12="امتثال −20",AC12="مخالفة −25",AC12="")),"✗ قائمة U",IF(AND(X12="لا",AC12<>"",AC12<>"لا خصم 0"),"✗ خصم",IF(AND(X12="نعم",AC12="لا خصم 0"),"✗ خصم",IF(AND(Z12="ممتاز 100%",AA12="ممتاز 100%",AB12<>"",AB12<>"مكتمل 100%"),"✗ إغلاق",IFERROR(IF(LEN(_xlfn.TEXTJOIN("، ",TRUE,IF(E12="","التاريخ",""),IF(F12="","الوقت",""),IF(G12="","المركز",""),IF(H12="","الدائرة",""),IF(I12="","القسم",""),IF(J12="","المسؤول",""),IF(K12="","نوع النشاط",""),IF(L12="","المشروع",""),IF(N12="","الممول",""),IF(V12="","الموضوع",""),IF(W12="","الملاحظة",""),IF(X12="","مشكلة",""),IF(Y12="","الإجراء",""),IF(Z12="","التنفيذ",""),IF(AA12="","الجودة",""),IF(AB12="","الإغلاق",""),IF(AC12="","الخصم",""),IF(AND(COUNTA($O12:$U12)>0,O12=""),"مدير المشروع",""),IF(AND(COUNTA($O12:$U12)>0,P12=""),"المستفيدين",""),IF(AND(COUNTA($O12:$U12)>0,Q12=""),"المناطق",""),IF(AND(COUNTA($O12:$U12)>0,R12=""),"الميزانية",""),IF(AND(COUNTA($O12:$U12)>0,S12=""),"نسبة الجاهزية",""),IF(AND(COUNTA($O12:$U12)>0,T12=""),"حالة الجاهزية",""),IF(AND(COUNTA($O12:$U12)>0,U12=""),"التوصيات","")))>0,"✗ ناقص: "&_xlfn.TEXTJOIN("، ",TRUE,IF(E12="","التاريخ",""),IF(F12="","الوقت",""),IF(G12="","المركز",""),IF(H12="","الدائرة",""),IF(I12="","القسم",""),IF(J12="","المسؤول",""),IF(K12="","نوع النشاط",""),IF(L12="","المشروع",""),IF(N12="","الممول",""),IF(V12="","الموضوع",""),IF(W12="","الملاحظة",""),IF(X12="","مشكلة",""),IF(Y12="","الإجراء",""),IF(Z12="","التنفيذ",""),IF(AA12="","الجودة",""),IF(AB12="","الإغلاق",""),IF(AC12="","الخصم",""),IF(AND(COUNTA($O12:$U12)>0,O12=""),"مدير المشروع",""),IF(AND(COUNTA($O12:$U12)>0,P12=""),"المستفيدين",""),IF(AND(COUNTA($O12:$U12)>0,Q12=""),"المناطق",""),IF(AND(COUNTA($O12:$U12)>0,R12=""),"الميزانية",""),IF(AND(COUNTA($O12:$U12)>0,S12=""),"نسبة الجاهزية",""),IF(AND(COUNTA($O12:$U12)>0,T12=""),"حالة الجاهزية",""),IF(AND(COUNTA($O12:$U12)>0,U12=""),"التوصيات","")),"✓"),"✓")))))))))) -> ✗ هرم | E12: 46120 | F12: 0.45833333 | G12: منسق المشروع | H12: دائرة الشؤون المالية | I12: جهاد أبو الريش / انيس حسن | J12: محمد إبراهيم عودة بدوان | K12: فحص مخزون | V12: متابعة استلام رول كاشير — مركز يافا | W12: استلام 150 رول كاشير وتسليمها لمركز يافا | X12: لا | Y12: مذكرة تذكيرية | Z12: ممتاز 100% | AA12: ممتاز 100% | AB12: مكتمل 100% | AC12: لا خصم 0 | AD12: اياد أبو عبدو | AE12: =IFERROR(VLOOKUP(Z12,LISTS!$AL$2:$AM$1000,2,FALSE()),"") -> 100 | AF12: =IFERROR(VLOOKUP(AA12,LISTS!$AO$2:$AP$1000,2,FALSE()),"") -> 100 | AG12: =IFERROR(VLOOKUP(AB12,LISTS!$AR$2:$AS$1000,2,FALSE()),"") -> 100 | AH12: =IFERROR(VLOOKUP(AC12,LISTS!$AU$2:$AV$1000,2,FALSE()),"") -> 0 | AI12: =IF(OR(AE12="",AF12="",AG12=""),"—",IFERROR(ROUND(AE12*0.4+AF12*0.3+AG12*0.3-IF(ISNUMBER(AH12),AH12,0),1),"⚠️")) -> 100 | AJ12: =IF(AI12="—","—",IF(NOT(ISNUMBER(AI12)),"⚠️",IF(AI12>=98,"🌟 ممتاز جدًا",IF(AI12>=90,"⭐ ممتاز",IF(AI12>=75,"🟢 جيد",IF(AI12>=60,"🟡 مقبول",IF(AI12>=40,"🔴 ضعيف","🚨 خطر شديد"))))))) -> 🌟 ممتاز جدًا | AK12: =IF(E12="","",MONTH(E12)) -> 4 | AL12: =IF(E12="","",YEAR(E12)) -> 2026
A13: =IF(I13<>"",COUNTA($I$2:I13),"") -> 12 | B13: =IF(E13="","",CHOOSE(WEEKDAY(E13,2),"الاثنين","الثلاثاء","الأربعاء","الخميس","الجمعة","السبت","الأحد")) -> الخميس | C13: 21 – 25/ يونيو 2026 | D13: =IF(AND(G13="",H13="",I13=""),"",IF(COUNTIFS(LISTS!$A$2:$A$67,G13,LISTS!$B$2:$B$67,H13,LISTS!$C$2:$C$67,I13)=0,"✗ هرم",IF(NOT(OR(Z13="ممتاز 100%",Z13="جيد 80%",Z13="مقبول 60%",Z13="خطر 40%",Z13="")),"✗ قائمة R",IF(NOT(OR(AA13="ممتاز 100%",AA13="جيد 85%",AA13="مقبول 70%",AA13="ضعيف 50%",AA13="")),"✗ قائمة S",IF(NOT(OR(AB13="مكتمل 100%",AB13="جزئي 60%",AB13="معلق 30%",AB13="مفتوح 0%",AB13="")),"✗ قائمة T",IF(NOT(OR(AC13="لا خصم 0",AC13="تأخير −5",AC13="عجز −10",AC13="جودة −15",AC13="امتثال −20",AC13="مخالفة −25",AC13="")),"✗ قائمة U",IF(AND(X13="لا",AC13<>"",AC13<>"لا خصم 0"),"✗ خصم",IF(AND(X13="نعم",AC13="لا خصم 0"),"✗ خصم",IF(AND(Z13="ممتاز 100%",AA13="ممتاز 100%",AB13<>"",AB13<>"مكتمل 100%"),"✗ إغلاق",IFERROR(IF(LEN(_xlfn.TEXTJOIN("، ",TRUE,IF(E13="","التاريخ",""),IF(F13="","الوقت",""),IF(G13="","المركز",""),IF(H13="","الدائرة",""),IF(I13="","القسم",""),IF(J13="","المسؤول",""),IF(K13="","نوع النشاط",""),IF(L13="","المشروع",""),IF(N13="","الممول",""),IF(V13="","الموضوع",""),IF(W13="","الملاحظة",""),IF(X13="","مشكلة",""),IF(Y13="","الإجراء",""),IF(Z13="","التنفيذ",""),IF(AA13="","الجودة",""),IF(AB13="","الإغلاق",""),IF(AC13="","الخصم",""),IF(AND(COUNTA($O13:$U13)>0,O13=""),"مدير المشروع",""),IF(AND(COUNTA($O13:$U13)>0,P13=""),"المستفيدين",""),IF(AND(COUNTA($O13:$U13)>0,Q13=""),"المناطق",""),IF(AND(COUNTA($O13:$U13)>0,R13=""),"الميزانية",""),IF(AND(COUNTA($O13:$U13)>0,S13=""),"نسبة الجاهزية",""),IF(AND(COUNTA($O13:$U13)>0,T13=""),"حالة الجاهزية",""),IF(AND(COUNTA($O13:$U13)>0,U13=""),"التوصيات","")))>0,"✗ ناقص: "&_xlfn.TEXTJOIN("، ",TRUE,IF(E13="","التاريخ",""),IF(F13="","الوقت",""),IF(G13="","المركز",""),IF(H13="","الدائرة",""),IF(I13="","القسم",""),IF(J13="","المسؤول",""),IF(K13="","نوع النشاط",""),IF(L13="","المشروع",""),IF(N13="","الممول",""),IF(V13="","الموضوع",""),IF(W13="","الملاحظة",""),IF(X13="","مشكلة",""),IF(Y13="","الإجراء",""),IF(Z13="","التنفيذ",""),IF(AA13="","الجودة",""),IF(AB13="","الإغلاق",""),IF(AC13="","الخصم",""),IF(AND(COUNTA($O13:$U13)>0,O13=""),"مدير المشروع",""),IF(AND(COUNTA($O13:$U13)>0,P13=""),"المستفيدين",""),IF(AND(COUNTA($O13:$U13)>0,Q13=""),"المناطق",""),IF(AND(COUNTA($O13:$U13)>0,R13=""),"الميزانية",""),IF(AND(COUNTA($O13:$U13)>0,S13=""),"نسبة الجاهزية",""),IF(AND(COUNTA($O13:$U13)>0,T13=""),"حالة الجاهزية",""),IF(AND(COUNTA($O13:$U13)>0,U13=""),"التوصيات","")),"✓"),"✓")))))))))) -> ✗ هرم | E13: 46121 | F13: 0.5 | G13: الجمعية | H13: دائرة الشؤون المالية | I13: مخيم المناصرة / مخيم أبو هاشم | J13: محمد إبراهيم عودة بدوان | K13: فحص مخزون | V13: متابعة استلام مواد غذائية — قسم المخازن | W13: 250 كيلو سكر + 100 وقية قهوة بن زحيمان | X13: لا | Y13: مذكرة تذكيرية | Z13: ممتاز 100% | AA13: ممتاز 100% | AB13: مكتمل 100% | AC13: لا خصم 0 | AD13: اياد أبو عبدو | AE13: =IFERROR(VLOOKUP(Z13,LISTS!$AL$2:$AM$1000,2,FALSE()),"") -> 100 | AF13: =IFERROR(VLOOKUP(AA13,LISTS!$AO$2:$AP$1000,2,FALSE()),"") -> 100 | AG13: =IFERROR(VLOOKUP(AB13,LISTS!$AR$2:$AS$1000,2,FALSE()),"") -> 100 | AH13: =IFERROR(VLOOKUP(AC13,LISTS!$AU$2:$AV$1000,2,FALSE()),"") -> 0 | AI13: =IF(OR(AE13="",AF13="",AG13=""),"—",IFERROR(ROUND(AE13*0.4+AF13*0.3+AG13*0.3-IF(ISNUMBER(AH13),AH13,0),1),"⚠️")) -> 100 | AJ13: =IF(AI13="—","—",IF(NOT(ISNUMBER(AI13)),"⚠️",IF(AI13>=98,"🌟 ممتاز جدًا",IF(AI13>=90,"⭐ ممتاز",IF(AI13>=75,"🟢 جيد",IF(AI13>=60,"🟡 مقبول",IF(AI13>=40,"🔴 ضعيف","🚨 خطر شديد"))))))) -> 🌟 ممتاز جدًا | AK13: =IF(E13="","",MONTH(E13)) -> 4 | AL13: =IF(E13="","",YEAR(E13)) -> 2026
A14: =IF(I14<>"",COUNTA($I$2:I14),"") -> 13 | B14: =IF(E14="","",CHOOSE(WEEKDAY(E14,2),"الاثنين","الثلاثاء","الأربعاء","الخميس","الجمعة","السبت","الأحد")) -> الخميس | C14: {=IF(E14="","",IF(M14<>"", M14&"/"&SUMPRODUCT((M$2:M14=M14)*1)&" - "&(ROW()-2), "إداري/"&SUMPRODUCT((M$2:M14="")*1)&" - "&(ROW()-2)))} -> إداري/13 - 12 | D14: =IF(AND(G14="",H14="",I14=""),"",IF(COUNTIFS(LISTS!$A$2:$A$67,G14,LISTS!$B$2:$B$67,H14,LISTS!$C$2:$C$67,I14)=0,"✗ هرم",IF(NOT(OR(Z14="ممتاز 100%",Z14="جيد 80%",Z14="مقبول 60%",Z14="خطر 40%",Z14="")),"✗ قائمة R",IF(NOT(OR(AA14="ممتاز 100%",AA14="جيد 85%",AA14="مقبول 70%",AA14="ضعيف 50%",AA14="")),"✗ قائمة S",IF(NOT(OR(AB14="مكتمل 100%",AB14="جزئي 60%",AB14="معلق 30%",AB14="مفتوح 0%",AB14="")),"✗ قائمة T",IF(NOT(OR(AC14="لا خصم 0",AC14="تأخير −5",AC14="عجز −10",AC14="جودة −15",AC14="امتثال −20",AC14="مخالفة −25",AC14="")),"✗ قائمة U",IF(AND(X14="لا",AC14<>"",AC14<>"لا خصم 0"),"✗ خصم",IF(AND(X14="نعم",AC14="لا خصم 0"),"✗ خصم",IF(AND(Z14="ممتاز 100%",AA14="ممتاز 100%",AB14<>"",AB14<>"مكتمل 100%"),"✗ إغلاق",IFERROR(IF(LEN(_xlfn.TEXTJOIN("، ",TRUE,IF(E14="","التاريخ",""),IF(F14="","الوقت",""),IF(G14="","المركز",""),IF(H14="","الدائرة",""),IF(I14="","القسم",""),IF(J14="","المسؤول",""),IF(K14="","نوع النشاط",""),IF(L14="","المشروع",""),IF(N14="","الممول",""),IF(V14="","الموضوع",""),IF(W14="","الملاحظة",""),IF(X14="","مشكلة",""),IF(Y14="","الإجراء",""),IF(Z14="","التنفيذ",""),IF(AA14="","الجودة",""),IF(AB14="","الإغلاق",""),IF(AC14="","الخصم",""),IF(AND(COUNTA($O14:$U14)>0,O14=""),"مدير المشروع",""),IF(AND(COUNTA($O14:$U14)>0,P14=""),"المستفيدين",""),IF(AND(COUNTA($O14:$U14)>0,Q14=""),"المناطق",""),IF(AND(COUNTA($O14:$U14)>0,R14=""),"الميزانية",""),IF(AND(COUNTA($O14:$U14)>0,S14=""),"نسبة الجاهزية",""),IF(AND(COUNTA($O14:$U14)>0,T14=""),"حالة الجاهزية",""),IF(AND(COUNTA($O14:$U14)>0,U14=""),"التوصيات","")))>0,"✗ ناقص: "&_xlfn.TEXTJOIN("، ",TRUE,IF(E14="","التاريخ",""),IF(F14="","الوقت",""),IF(G14="","المركز",""),IF(H14="","الدائرة",""),IF(I14="","القسم",""),IF(J14="","المسؤول",""),IF(K14="","نوع النشاط",""),IF(L14="","المشروع",""),IF(N14="","الممول",""),IF(V14="","الموضوع",""),IF(W14="","الملاحظة",""),IF(X14="","مشكلة",""),IF(Y14="","الإجراء",""),IF(Z14="","التنفيذ",""),IF(AA14="","الجودة",""),IF(AB14="","الإغلاق",""),IF(AC14="","الخصم",""),IF(AND(COUNTA($O14:$U14)>0,O14=""),"مدير المشروع",""),IF(AND(COUNTA($O14:$U14)>0,P14=""),"المستفيدين",""),IF(AND(COUNTA($O14:$U14)>0,Q14=""),"المناطق",""),IF(AND(COUNTA($O14:$U14)>0,R14=""),"الميزانية",""),IF(AND(COUNTA($O14:$U14)>0,S14=""),"نسبة الجاهزية",""),IF(AND(COUNTA($O14:$U14)>0,T14=""),"حالة الجاهزية",""),IF(AND(COUNTA($O14:$U14)>0,U14=""),"التوصيات","")),"✓"),"✓")))))))))) -> ✗ ناقص: الممول | E14: 46121 | F14: 0.5 | G14: الجمعية | H14: دائرة الاستثمار الخيري | I14: مطبخ البركة | J14: باسم ديب عبد الله المبحوح | K14: جودة خدمة | L14: وجبات ساخنة | V14: زيارة مطبخ البركة — متابعة تجهيز وجبات | W14: 200 وجبة مفرد تم تجهيزها | X14: لا | Y14: مذكرة تذكيرية | Z14: ممتاز 100% | AA14: ممتاز 100% | AB14: مكتمل 100% | AC14: لا خصم 0 | AD14: اياد أبو عبدو | AE14: =IFERROR(VLOOKUP(Z14,LISTS!$AL$2:$AM$1000,2,FALSE()),"") -> 100 | AF14: =IFERROR(VLOOKUP(AA14,LISTS!$AO$2:$AP$1000,2,FALSE()),"") -> 100 | AG14: =IFERROR(VLOOKUP(AB14,LISTS!$AR$2:$AS$1000,2,FALSE()),"") -> 100 | AH14: =IFERROR(VLOOKUP(AC14,LISTS!$AU$2:$AV$1000,2,FALSE()),"") -> 0 | AI14: =IF(OR(AE14="",AF14="",AG14=""),"—",IFERROR(ROUND(AE14*0.4+AF14*0.3+AG14*0.3-IF(ISNUMBER(AH14),AH14,0),1),"⚠️")) -> 100 | AJ14: =IF(AI14="—","—",IF(NOT(ISNUMBER(AI14)),"⚠️",IF(AI14>=98,"🌟 ممتاز جدًا",IF(AI14>=90,"⭐ ممتاز",IF(AI14>=75,"🟢 جيد",IF(AI14>=60,"🟡 مقبول",IF(AI14>=40,"🔴 ضعيف","🚨 خطر شديد"))))))) -> 🌟 ممتاز جدًا | AK14: =IF(E14="","",MONTH(E14)) -> 4 | AL14: =IF(E14="","",YEAR(E14)) -> 2026
